Workbook
Name TC: 'RESUMEN GLOBAL'!$E$3

Sheet DASHBOARD
B2: DASHBOARD — CONTROL DE REFACCIONES Y COTIZACIONES 2026
B3: Resumen de pedidos, cotizaciones y estado de maquinaria pesada
B5: 📊 RESUMEN DE PARTIDAS
B6: TOTAL PARTIDAS | C6: ENTREGADO | D6: COTIZANDO | E6: EN ALMACÉN | F6: CANCELADO | G6: PEDIDO
B7: =ROWS(Tabla3[PEDIDO]) -> 1326 | C7: =COUNTIF(Tabla3[STATUS],"ENTREGADO") -> 478 | D7: =COUNTIFS(Tabla3[STATUS],"COTIZANDO",Tabla3[TEMA],"<>SERVICIO DE FILTROS") -> 704 | E7: =COUNTIF(Tabla3[STATUS],"EN ALMACEN") -> 50 | F7: =COUNTIF(Tabla3[STATUS],"CANCELADO") -> 31 | G7: =COUNTIF(Tabla3[STATUS],"PEDIDO") -> 58
B8: piezas solicitadas | C8: =TEXT(C7/B7,"0%")&" del total" -> 36% del total | D8: =TEXT(D7/B7,"0%")&" del total" -> 53% del total | E8: =TEXT(E7/B7,"0%")&" del total" -> 4% del total | F8: =TEXT(F7/B7,"0%")&" del total" -> 2% del total | G8: por entregar
B10: 🚜 ESTADO DE MAQUINARIA
B11: UNIDADES ACTIVAS | C11: UNIDADES INACTIVAS | D11: UNIDADES DONANTE | E11: UNIDADES SINIESTRADAS | F11: TOTAL UNIDADES | G11: % DISPONIBILIDAD
B12: =COUNTIFS(MAQUINARIA!$B$3:$B$655,"<>",MAQUINARIA!$B$3:$B$655,"<>Seguimiento",MAQUINARIA!$H$3:$H$655,"ACTIVA") -> 81 | C12: =COUNTIFS(MAQUINARIA!$B$3:$B$655,"<>",MAQUINARIA!$B$3:$B$655,"<>Seguimiento",MAQUINARIA!$H$3:$H$655,"INACTIVA") -> 38 | D12: =COUNTIFS(MAQUINARIA!$B$3:$B$655,"<>",MAQUINARIA!$B$3:$B$655,"<>Seguimiento",MAQUINARIA!$H$3:$H$655,"DONANTE") -> 5 | E12: =COUNTIFS(MAQUINARIA!$B$3:$B$655,"<>",MAQUINARIA!$B$3:$B$655,"<>Seguimiento",MAQUINARIA!$H$3:$H$655,"SINIESTRADO") -> 2 | F12: =SUM(B12:E12) -> 126 | G12: =IF(F12>0,B12/F12,0) -> 0.64285714
B13: en operación | C13: en reparación | D13: para refacciones | E13: fuera de operación | F13: flota total | G13: de la flota
B15: 💰 COMPARATIVO DE COSTOS — PARTIDAS EN COTIZACIÓN (Excluye Servicios de Filtros)
B16: MATCO (MXN) | C16: HAWTHORNE (USD) | D16: CTP (USD) | E16: TIPO DE CAMBIO
B17: =SUMIFS(Tabla3[COSTO TOTAL SIN IVA PESOS EN MATCO],Tabla3[STATUS],"COTIZANDO",Tabla3[TEMA],"<>SERVICIO DE FILTROS") -> 6047672 | C17: =SUMIFS(Tabla3[COSTO TOTAL DOLARES EN HAWTHORNE],Tabla3[STATUS],"COTIZANDO",Tabla3[TEMA],"<>SERVICIO DE FILTROS") -> 191410.88 | D17: =SUMIFS(Tabla3[COSTO TOTAL DOLARES CTP],Tabla3[STATUS],"COTIZANDO",Tabla3[TEMA],"<>SERVICIO DE FILTROS") -> 23109.76 | E17: =IF('RESUMEN GLOBAL'!E3="","$0.00 MXN/USD","$"&TEXT('RESUMEN GLOBAL'!E3,"#,##0.00")&" MXN/USD") -> $17.00 MXN/USD
B18: pesos sin IVA | C18: dólares | D18: dólares | E18: capturado en Resumen
B20: 🔧 MONTOS PARA REPARACIÓN DE UNIDADES INACTIVAS
B21: NÚM. ECON. | C21: MODELO | D21: ESTATUS | E21: COSTO MATCO (MXN) | F21: COSTO CTP (USD) | G21: COSTO HAWTHORNE (USD)
B22: {=IFERROR(INDEX(_xlfn._xlws.FILTER('RESUMEN GLOBAL'!B12:B25,'RESUMEN GLOBAL'!C12:C25="INACTIVA"),1),"")} -> CL-01 | C22: {=IFERROR(INDEX(_xlfn._xlws.FILTER('RESUMEN GLOBAL'!D12:D25,'RESUMEN GLOBAL'!C12:C25="INACTIVA"),1),"")} -> CAMION DE LAVADO 650 | D22: =IF(B22<>"","INACTIVA","") -> INACTIVA | E22: {=IFERROR(INDEX(_xlfn._xlws.FILTER('RESUMEN GLOBAL'!G12:G25,'RESUMEN GLOBAL'!C12:C25="INACTIVA"),1),0)} -> 0 | F22: =IF(B22="",0,IFERROR(_xlfn.NUMBERVALUE(SUBSTITUTE(SUBSTITUTE(_xlfn.XLOOKUP(B22,'RESUMEN GLOBAL'!$B$12:$B$25,'RESUMEN GLOBAL'!$J$12:$J$25)," USD",""),"$",""),".",","),0)) -> 0 | G22: =IF(B22="",0,IFERROR(_xlfn.NUMBERVALUE(SUBSTITUTE(SUBSTITUTE(_xlfn.XLOOKUP(B22,'RESUMEN GLOBAL'!$B$12:$B$25,'RESUMEN GLOBAL'!$H$12:$H$25)," USD",""),"$",""),".",","),0)) -> 0
B23: {=IFERROR(INDEX(_xlfn._xlws.FILTER('RESUMEN GLOBAL'!B12:B25,'RESUMEN GLOBAL'!C12:C25="INACTIVA"),2),"")} -> CM-04 | C23: {=IFERROR(INDEX(_xlfn._xlws.FILTER('RESUMEN GLOBAL'!D12:D25,'RESUMEN GLOBAL'!C12:C25="INACTIVA"),2),"")} -> CAMA BAJA DOLLY | D23: =IF(B23<>"","INACTIVA","") -> INACTIVA | E23: {=IFERROR(INDEX(_xlfn._xlws.FILTER('RESUMEN GLOBAL'!G12:G25,'RESUMEN GLOBAL'!C12:C25="INACTIVA"),2),0)} -> 0 | F23: =IF(B23="",0,IFERROR(_xlfn.NUMBERVALUE(SUBSTITUTE(SUBSTITUTE(_xlfn.XLOOKUP(B23,'RESUMEN GLOBAL'!$B$12:$B$25,'RESUMEN GLOBAL'!$J$12:$J$25)," USD",""),"$",""),".",","),0)) -> 0 | G23: =IF(B23="",0,IFERROR(_xlfn.NUMBERVALUE(SUBSTITUTE(SUBSTITUTE(_xlfn.XLOOKUP(B23,'RESUMEN GLOBAL'!$B$12:$B$25,'RESUMEN GLOBAL'!$H$12:$H$25)," USD",""),"$",""),".",","),0)) -> 0
B24: {=IFERROR(INDEX(_xlfn._xlws.FILTER('RESUMEN GLOBAL'!B12:B25,'RESUMEN GLOBAL'!C12:C25="INACTIVA"),3),"")} -> CRC-04 | C24: {=IFERROR(INDEX(_xlfn._xlws.FILTER('RESUMEN GLOBAL'!D12:D25,'RESUMEN GLOBAL'!C12:C25="INACTIVA"),3),"")} -> CAMION REVOLVEDOR 7 MTS | D24: =IF(B24<>"","INACTIVA","") -> INACTIVA | E24: {=IFERROR(INDEX(_xlfn._xlws.FILTER('RESUMEN GLOBAL'!G12:G25,'RESUMEN GLOBAL'!C12:C25="INACTIVA"),3),0)} -> 0 | F24: =IF(B24="",0,IFERROR(_xlfn.NUMBERVALUE(SUBSTITUTE(SUBSTITUTE(_xlfn.XLOOKUP(B24,'RESUMEN GLOBAL'!$B$12:$B$25,'RESUMEN GLOBAL'!$J$12:$J$25)," USD",""),"$",""),".",","),0)) -> 0 | G24: =IF(B24="",0,IFERROR(_xlfn.NUMBERVALUE(SUBSTITUTE(SUBSTITUTE(_xlfn.XLOOKUP(B24,'RESUMEN GLOBAL'!$B$12:$B$25,'RESUMEN GLOBAL'!$H$12:$H$25)," USD",""),"$",""),".",","),0)) -> 0
B25: {=IFERROR(INDEX(_xlfn._xlws.FILTER('RESUMEN GLOBAL'!B12:B25,'RESUMEN GLOBAL'!C12:C25="INACTIVA"),4),"")} | C25: {=IFERROR(INDEX(_xlfn._xlws.FILTER('RESUMEN GLOBAL'!D12:D25,'RESUMEN GLOBAL'!C12:C25="INACTIVA"),4),"")} | D25: =IF(B25<>"","INACTIVA","") | E25: {=IFERROR(INDEX(_xlfn._xlws.FILTER('RESUMEN GLOBAL'!G12:G25,'RESUMEN GLOBAL'!C12:C25="INACTIVA"),4),0)} -> 0 | F25: =IF(B25="",0,IFERROR(_xlfn.NUMBERVALUE(SUBSTITUTE(SUBSTITUTE(_xlfn.XLOOKUP(B25,'RESUMEN GLOBAL'!$B$12:$B$25,'RESUMEN GLOBAL'!$J$12:$J$25)," USD",""),"$",""),".",","),0)) -> 0 | G25: =IF(B25="",0,IFERROR(_xlfn.NUMBERVALUE(SUBSTITUTE(SUBSTITUTE(_xlfn.XLOOKUP(B25,'RESUMEN GLOBAL'!$B$12:$B$25,'RESUMEN GLOBAL'!$H$12:$H$25)," USD",""),"$",""),".",","),0)) -> 0
B26: {=IFERROR(INDEX(_xlfn._xlws.FILTER('RESUMEN GLOBAL'!B12:B25,'RESUMEN GLOBAL'!C12:C25="INACTIVA"),5),"")} | C26: {=IFERROR(INDEX(_xlfn._xlws.FILTER('RESUMEN GLOBAL'!D12:D25,'RESUMEN GLOBAL'!C12:C25="INACTIVA"),5),"")} | D26: =IF(B26<>"","INACTIVA","") | E26: {=IFERROR(INDEX(_xlfn._xlws.FILTER('RESUMEN GLOBAL'!G12:G25,'RESUMEN GLOBAL'!C12:C25="INACTIVA"),5),0)} -> 0 | F26: =IF(B26="",0,IFERROR(_xlfn.NUMBERVALUE(SUBSTITUTE(SUBSTITUTE(_xlfn.XLOOKUP(B26,'RESUMEN GLOBAL'!$B$12:$B$25,'RESUMEN GLOBAL'!$J$12:$J$25)," USD",""),"$",""),".",","),0)) -> 0 | G26: =IF(B26="",0,IFERROR(_xlfn.NUMBERVALUE(SUBSTITUTE(SUBSTITUTE(_xlfn.XLOOKUP(B26,'RESUMEN GLOBAL'!$B$12:$B$25,'RESUMEN GLOBAL'!$H$12:$H$25)," USD",""),"$",""),".",","),0)) -> 0
B27: {=IFERROR(INDEX(_xlfn._xlws.FILTER('RESUMEN GLOBAL'!B12:B25,'RESUMEN GLOBAL'!C12:C25="INACTIVA"),6),"")} | C27: {=IFERROR(INDEX(_xlfn._xlws.FILTER('RESUMEN GLOBAL'!D12:D25,'RESUMEN GLOBAL'!C12:C25="INACTIVA"),6),"")} | D27: =IF(B27<>"","INACTIVA","") | E27: {=IFERROR(INDEX(_xlfn._xlws.FILTER('RESUMEN GLOBAL'!G12:G25,'RESUMEN GLOBAL'!C12:C25="INACTIVA"),6),0)} -> 0 | F27: =IF(B27="",0,IFERROR(_xlfn.NUMBERVALUE(SUBSTITUTE(SUBSTITUTE(_xlfn.XLOOKUP(B27,'RESUMEN GLOBAL'!$B$12:$B$25,'RESUMEN GLOBAL'!$J$12:$J$25)," USD",""),"$",""),".",","),0)) -> 0 | G27: =IF(B27="",0,IFERROR(_xlfn.NUMBERVALUE(SUBSTITUTE(SUBSTITUTE(_xlfn.XLOOKUP(B27,'RESUMEN GLOBAL'!$B$12:$B$25,'RESUMEN GLOBAL'!$H$12:$H$25)," USD",""),"$",""),".",","),0)) -> 0
B28: {=IFERROR(INDEX(_xlfn._xlws.FILTER('RESUMEN GLOBAL'!B12:B25,'RESUMEN GLOBAL'!C12:C25="INACTIVA"),7),"")} | C28: {=IFERROR(INDEX(_xlfn._xlws.FILTER('RESUMEN GLOBAL'!D12:D25,'RESUMEN GLOBAL'!C12:C25="INACTIVA"),7),"")} | D28: =IF(B28<>"","INACTIVA","") | E28: {=IFERROR(INDEX(_xlfn._xlws.FILTER('RESUMEN GLOBAL'!G12:G25,'RESUMEN GLOBAL'!C12:C25="INACTIVA"),7),0)} -> 0 | F28: =IF(B28="",0,IFERROR(_xlfn.NUMBERVALUE(SUBSTITUTE(SUBSTITUTE(_xlfn.XLOOKUP(B28,'RESUMEN GLOBAL'!$B$12:$B$25,'RESUMEN GLOBAL'!$J$12:$J$25)," USD",""),"$",""),".",","),0)) -> 0 | G28: =IF(B28="",0,IFERROR(_xlfn.NUMBERVALUE(SUBSTITUTE(SUBSTITUTE(_xlfn.XLOOKUP(B28,'RESUMEN GLOBAL'!$B$12:$B$25,'RESUMEN GLOBAL'!$H$12:$H$25)," USD",""),"$",""),".",","),0)) -> 0
B29: {=IFERROR(INDEX(_xlfn._xlws.FILTER('RESUMEN GLOBAL'!B12:B25,'RESUMEN GLOBAL'!C12:C25="INACTIVA"),8),"")} | C29: {=IFERROR(INDEX(_xlfn._xlws.FILTER('RESUMEN GLOBAL'!D12:D25,'RESUMEN GLOBAL'!C12:C25="INACTIVA"),8),"")} | D29: =IF(B29<>"","INACTIVA","") | E29: {=IFERROR(INDEX(_xlfn._xlws.FILTER('RESUMEN GLOBAL'!G12:G25,'RESUMEN GLOBAL'!C12:C25="INACTIVA"),8),0)} -> 0 | F29: =IF(B29="",0,IFERROR(_xlfn.NUMBERVALUE(SUBSTITUTE(SUBSTITUTE(_xlfn.XLOOKUP(B29,'RESUMEN GLOBAL'!$B$12:$B$25,'RESUMEN GLOBAL'!$J$12:$J$25)," USD",""),"$",""),".",","),0)) -> 0 | G29: =IF(B29="",0,IFERROR(_xlfn.NUMBERVALUE(SUBSTITUTE(SUBSTITUTE(_xlfn.XLOOKUP(B29,'RESUMEN GLOBAL'!$B$12:$B$25,'RESUMEN GLOBAL'!$H$12:$H$25)," USD",""),"$",""),".",","),0)) -> 0
B30: {=IFERROR(INDEX(_xlfn._xlws.FILTER('RESUMEN GLOBAL'!B12:B25,'RESUMEN GLOBAL'!C12:C25="INACTIVA"),9),"")} | C30: {=IFERROR(INDEX(_xlfn._xlws.FILTER('RESUMEN GLOBAL'!D12:D25,'RESUMEN GLOBAL'!C12:C25="INACTIVA"),9),"")} | D30: =IF(B30<>"","INACTIVA","") | E30: {=IFERROR(INDEX(_xlfn._xlws.FILTER('RESUMEN GLOBAL'!G12:G25,'RESUMEN GLOBAL'!C12:C25="INACTIVA"),9),0)} -> 0 | F30: =IF(B30="",0,IFERROR(_xlfn.NUMBERVALUE(SUBSTITUTE(SUBSTITUTE(_xlfn.XLOOKUP(B30,'RESUMEN GLOBAL'!$B$12:$B$25,'RESUMEN GLOBAL'!$J$12:$J$25)," USD",""),"$",""),".",","),0)) -> 0 | G30: =IF(B30="",0,IFERROR(_xlfn.NUMBERVALUE(SUBSTITUTE(SUBSTITUTE(_xlfn.XLOOKUP(B30,'RESUMEN GLOBAL'!$B$12:$B$25,'RESUMEN GLOBAL'!$H$12:$H$25)," USD",""),"$",""),".",","),0)) -> 0
B31: {=IFERROR(INDEX(_xlfn._xlws.FILTER('RESUMEN GLOBAL'!B12:B25,'RESUMEN GLOBAL'!C12:C25="INACTIVA"),10),"")} | C31: {=IFERROR(INDEX(_xlfn._xlws.FILTER('RESUMEN GLOBAL'!D12:D25,'RESUMEN GLOBAL'!C12:C25="INACTIVA"),10),"")} | D31: =IF(B31<>"","INACTIVA","") | E31: {=IFERROR(INDEX(_xlfn._xlws.FILTER('RESUMEN GLOBAL'!G12:G25,'RESUMEN GLOBAL'!C12:C25="INACTIVA"),10),0)} -> 0 | F31: =IF(B31="",0,IFERROR(_xlfn.NUMBERVALUE(SUBSTITUTE(SUBSTITUTE(_xlfn.XLOOKUP(B31,'RESUMEN GLOBAL'!$B$12:$B$25,'RESUMEN GLOBAL'!$J$12:$J$25)," USD",""),"$",""),".",","),0)) -> 0 | G31: =IF(B31="",0,IFERROR(_xlfn.NUMBERVALUE(SUBSTITUTE(SUBSTITUTE(_xlfn.XLOOKUP(B31,'RESUMEN GLOBAL'!$B$12:$B$25,'RESUMEN GLOBAL'!$H$12:$H$25)," USD",""),"$",""),".",","),0)) -> 0
B32: TOTAL REQUERIDO PARA REPARACIONES | E32: =SUM(E22:E31) -> 0 | F32: =SUM(F22:F31) -> 0 | G32: =SUM(G22:G31) -> 0
B35: 📈 RESUMEN COMPARATIVO DE PROVEEDORES
B36: PROVEEDOR | C36: PARTIDAS COTIZADAS | D36: COSTO TOTAL | E36: MONEDA
B37: MATCO | C37: =COUNTIFS(Tabla3[STATUS],"COTIZANDO",Tabla3[COSTO TOTAL SIN IVA PESOS EN MATCO],">0") -> 703 | D37: =SUMIF(Tabla3[STATUS],"COTIZANDO",Tabla3[COSTO TOTAL SIN IVA PESOS EN MATCO]) -> 6049092.5 | E37: MXN
B38: HAWTHORNE | C38: {=SUMPRODUCT((Tabla3[STATUS]="COTIZANDO")*(Tabla3[COSTO TOTAL DOLARES EN HAWTHORNE]>0)*1)} -> 190 | D38: =SUMIF(Tabla3[STATUS],"COTIZANDO",Tabla3[COSTO TOTAL DOLARES EN HAWTHORNE]) -> 191410.88 | E38: USD
B39: CTP | C39: {=SUMPRODUCT((Tabla3[STATUS]="COTIZANDO")*(Tabla3[COSTO TOTAL DOLARES CTP]>0)*1)} -> 153 | D39: =SUMIF(Tabla3[STATUS],"COTIZANDO",Tabla3[COSTO TOTAL DOLARES CTP]) -> 23109.76 | E39: USD
B42: 📌 Los datos se actualizan automáticamente desde las hojas CONTROL y MAQUINARIA. Capture el tipo de cambio en RESUMEN GLOBAL para ver conversiones a MXN.
B44: 🔧 SERVICIOS DE FILTROS — Costos Operativos (Separados)
B45: NÚM. ECON. | C45: PEDIDO | D45: PARTIDAS | E45: MATCO (MXN) | F45: CTP (USD)
B46: ='RESUMEN GLOBAL'!B136 -> TM-03 | C46: ='RESUMEN GLOBAL'!C136 -> Pedido 119 | D46: ='RESUMEN GLOBAL'!D136 -> 5 | E46: ='RESUMEN GLOBAL'!E136 -> 1420.55 | F46: ='RESUMEN GLOBAL'!H136 -> 0
B47: ='RESUMEN GLOBAL'!B137 | C47: ='RESUMEN GLOBAL'!C137 | D47: ='RESUMEN GLOBAL'!D137 | E47: ='RESUMEN GLOBAL'!E137 | F47: ='RESUMEN GLOBAL'!H137
B48: ='RESUMEN GLOBAL'!B145 -> TOTAL FILTROS | D48: ='RESUMEN GLOBAL'!D145 -> 5 | E48: ='RESUMEN GLOBAL'!E145 -> 1420.55 | F48: ='RESUMEN GLOBAL'!H145 -> 0

Sheet CONTROL
A1: PEDIDO | B1: FECHA DE SOLICITUD | C1: QUIEN SOLICITA | D1: OC | E1: REQUISICION | F1: FECHA DE REQ | G1: ESTATUS DE NUM ECONOMICO | H1: NUM ECONOMICO | I1: NUMERO DE PARTE | J1: DESCRIPCION | K1: CANTIDAD SOLICTADA | L1: COSTO UNITARIO EN MATCO PESOS | M1: COSTO TOTAL SIN IVA PESOS EN MATCO | N1: DIAS DE ENTREGA TENTATIVO EN MATCO | O1: COSTO UNITARIO DOLARES EN HAWTHORNE | P1: COSTO TOTAL DOLARES EN HAWTHORNE | Q1: DIAS TENTATIVO DE ENTREGA HAWTHORNE | R1: COSTO UNITARIO DOLARES CTP | S1: COSTO TOTAL DOLARES CTP | T1: DIAS TENTATIVO DE ENTREGA CTP | U1: STATUS | V1: NUMERO DE COTIZACION | W1: FECHA DE ENTREGA | X1: EN ESTOCK | Y1: CANTIDAD EN ESTOCK | Z1: PEDIDO A PROVEEDOR | AA1: FECHA DE PEDIDO | AB1: FECHA TENTATIVA DE ENTREGA | AC1: QUIEN RECIBE | AD1: REMISION DE SALIDA | AE1: COMENTARIOS | AF1: COMENTARIOS 2 | AG1: TEMA
A2: 1 | B2: 46163 | C2: SERGIO | E2: 16 | F2: 46171 | G2: =IFERROR(VLOOKUP(Tabla3[[#This Row],[NUM ECONOMICO]],MAQUINARIA!B:H,7,0), " MAQ") -> ACTIVA | H2: MR-01 | I2: 5917178 | K2: 2 | M2: =+L2*K2 -> 0 | P2: =Tabla3[[#This Row],[COSTO UNITARIO DOLARES EN HAWTHORNE]]*Tabla3[[#This Row],[CANTIDAD SOLICTADA]] -> 0 | S2: =+Tabla3[[#This Row],[COSTO UNITARIO DOLARES CTP]]*Tabla3[[#This Row],[CANTIDAD SOLICTADA]] -> 0 | U2: ENTREGADO | V2: QT-08-427805 | W2: 46170 | X2: NO | Y2: SIN EXISTENCIA | Z2: MATCO | AA2: 46167 | AB2: 46170 | AC2: JAVIER G
A3: 1 | B3: 46163 | C3: SERGIO | E3: 16 | F3: 46171 | G3: =IFERROR(VLOOKUP(Tabla3[[#This Row],[NUM ECONOMICO]],MAQUINARIA!B:H,7,0), " MAQ") -> ACTIVA | H3: MR-01 | I3: 1218167 | K3: 2 | M3: =+L3*K3 -> 0 | P3: =Tabla3[[#This Row],[COSTO UNITARIO DOLARES EN HAWTHORNE]]*Tabla3[[#This Row],[CANTIDAD SOLICTADA]] -> 0 | S3: =+Tabla3[[#This Row],[COSTO UNITARIO DOLARES CTP]]*Tabla3[[#This Row],[CANTIDAD SOLICTADA]] -> 0 | U3: ENTREGADO | V3: QT-08-427805 | W3: 46170 | X3: NO | Y3: SIN EXISTENCIA | Z3: MATCO | AA3: 46167 | AB3: 46170 | AC3: JAVIER G
A4: 1 | B4: 46163 | C4: SERGIO | E4: 16 | F4: 46171 | G4: =IFERROR(VLOOKUP(Tabla3[[#This Row],[NUM ECONOMICO]],MAQUINARIA!B:H,7,0), " MAQ") -> ACTIVA | H4: MR-01 | I4: 4364462 | K4: 2 | M4: =+L4*K4 -> 0 | P4: =Tabla3[[#This Row],[COSTO UNITARIO DOLARES EN HAWTHORNE]]*Tabla3[[#This Row],[CANTIDAD SOLICTADA]] -> 0 | S4: =+Tabla3[[#This Row],[COSTO UNITARIO DOLARES CTP]]*Tabla3[[#This Row],[CANTIDAD SOLICTADA]] -> 0 | U4: ENTREGADO | V4: QT-08-427805 | W4: 46170 | X4: NO | Y4: SIN EXISTENCIA | Z4: MATCO | AA4: 46167 | AB4: 46170 | AC4: JAVIER G
A5: 1 | B5: 46163 | C5: SERGIO | E5: 16 | F5: 46171 | G5: =IFERROR(VLOOKUP(Tabla3[[#This Row],[NUM ECONOMICO]],MAQUINARIA!B:H,7,0), " MAQ") -> ACTIVA | H5: MR-01 | I5: 7X5762 | K5: 1 | M5: =+L5*K5 -> 0 | P5: =Tabla3[[#This Row],[COSTO UNITARIO DOLARES EN HAWTHORNE]]*Tabla3[[#This Row],[CANTIDAD SOLICTADA]] -> 0 | S5: =+Tabla3[[#This Row],[COSTO UNITARIO DOLARES CTP]]*Tabla3[[#This Row],[CANTIDAD SOLICTADA]] -> 0 | U5: ENTREGADO | V5: QT-08-427805 | W5: 46170 | X5: NO | Y5: SIN EXISTENCIA | Z5: MATCO | AA5: 46167 | AB5: 46170 | AC5: JAVIER G
A6: 1 | B6: 46163 | C6: SERGIO | E6: 16 | F6: 46171 | G6: =IFERROR(VLOOKUP(Tabla3[[#This Row],[NUM ECONOMICO]],MAQUINARIA!B:H,7,0), " MAQ") -> ACTIVA | H6: MR-01 | I6: 4826731 | K6: 8 | M6: =+L6*K6 -> 0 | P6: =Tabla3[[#This Row],[COSTO UNITARIO DOLARES EN HAWTHORNE]]*Tabla3[[#This Row],[CANTIDAD SOLICTADA]] -> 0 | S6: =+Tabla3[[#This Row],[COSTO UNITARIO DOLARES CTP]]*Tabla3[[#This Row],[CANTIDAD SOLICTADA]] -> 0 | U6: ENTREGADO | V6: QT-08-427805 | W6: 46170 | X6: NO | Y6: SIN EXISTENCIA | Z6: MATCO | AA6: 46167 | AB6: 46170 | AC6: JAVIER G
A7: 1 | B7: 46163 | C7: SERGIO | E7: 16 | F7: 46171 | G7: =IFERROR(VLOOKUP(Tabla3[[#This Row],[NUM ECONOMICO]],MAQUINARIA!B:H,7,0), " MAQ") -> ACTIVA | H7: MR-01 | I7: 4858330 | K7: 8 | M7: =+L7*K7 -> 0 | P7: =Tabla3[[#This Row],[COSTO UNITARIO DOLARES EN HAWTHORNE]]*Tabla3[[#This Row],[CANTIDAD SOLICTADA]] -> 0 | S7: =+Tabla3[[#This Row],[COSTO UNITARIO DOLARES CTP]]*Tabla3[[#This Row],[CANTIDAD SOLICTADA]] -> 0 | U7: ENTREGADO | V7: QT-08-427805 | W7: 46170 | X7: NO | Y7: SIN EXISTENCIA | Z7: MATCO | AA7: 46167 | AB7: 46170 | AC7: JAVIER G
A8: 1 | B8: 46163 | C8: SERGIO | E8: 16 | F8: 46171 | G8: =IFERROR(VLOOKUP(Tabla3[[#This Row],[NUM ECONOMICO]],MAQUINARIA!B:H,7,0), " MAQ") -> ACTIVA | H8: MR-01 | I8: 3752548 | K8: 1 | M8: =+L8*K8 -> 0 | P8: =Tabla3[[#This Row],[COSTO UNITARIO DOLARES EN HAWTHORNE]]*Tabla3[[#This Row],[CANTIDAD SOLICTADA]] -> 0 | S8: =+Tabla3[[#This Row],[COSTO UNITARIO DOLARES CTP]]*Tabla3[[#This Row],[CANTIDAD SOLICTADA]] -> 0 | U8: ENTREGADO | V8: QT-08-427805 | W8: 46170 | X8: NO | Y8: SIN EXISTENCIA | Z8: MATCO | AA8: 46167 | AB8: 46170 | AC8: JAVIER G
A9: 1 | B9: 46163 | C9: SERGIO | E9: 16 | F9: 46171 | G9: =IFERROR(VLOOKUP(Tabla3[[#This Row],[NUM ECONOMICO]],MAQUINARIA!B:H,7,0), " MAQ") -> ACTIVA | H9: MR-01 | I9: 4945603 | K9: 1 | M9: =+L9*K9 -> 0 | P9: =Tabla3[[#This Row],[COSTO UNITARIO DOLARES EN HAWTHORNE]]*Tabla3[[#This Row],[CANTIDAD SOLICTADA]] -> 0 | S9: =+Tabla3[[#This Row],[COSTO UNITARIO DOLARES CTP]]*Tabla3[[#This Row],[CANTIDAD SOLICTADA]] -> 0 | U9: ENTREGADO | V9: QT-08-427805 | W9: 46181 | X9: NO | Y9: SIN EXISTENCIA | AE9: COMENTA BENJAMIN QUE YA SE ENTREGO
A10: 2 | B10: 46163 | C10: SERGIO | G10: =IFERROR(VLOOKUP(Tabla3[[#This Row],[NUM ECONOMICO]],MAQUINARIA!B:H,7,0), " MAQ") -> ACTIVA | H10: MT-08 | I10: 1P3705 | K10: 30 | M10: =+L10*K10 -> 0 | P10: =Tabla3[[#This Row],[COSTO UNITARIO DOLARES EN HAWTHORNE]]*Tabla3[[#This Row],[CANTIDAD SOLICTADA]] -> 0 | S10: =+Tabla3[[#This Row],[COSTO UNITARIO DOLARES CTP]]*Tabla3[[#This Row],[CANTIDAD SOLICTADA]] -> 0 | U10: ENTREGADO | X10: SI | Y10: 6
A11: 2 | B11: 46163 | C11: SERGIO | E11: 1028 | F11: 45952 | G11: =IFERROR(VLOOKUP(Tabla3[[#This Row],[NUM ECONOMICO]],MAQUINARIA!B:H,7,0), " MAQ") -> ACTIVA | H11: MT-08 | I11: 4C4782 / 2701528 | K11: 2 | L11: 25068.48 | M11: =+L11*K11 -> 50136.96 | P11: =Tabla3[[#This Row],[COSTO UNITARIO DOLARES EN HAWTHORNE]]*Tabla3[[#This Row],[CANTIDAD SOLICTADA]] -> 0 | S11: =+Tabla3[[#This Row],[COSTO UNITARIO DOLARES CTP]]*Tabla3[[#This Row],[CANTIDAD SOLICTADA]] -> 0 | U11: ENTREGADO | V11: QT-08-427516 | X11: NO | Y11: SIN EXISTENCIA | AE11: ENTREGADO A BENJAMIN POSIBLE COMPRA CTP | AF11: SOLICITAR A BENJA COMPRA EN CTP | AG11: MALETIN DE SELLOS
A12: 3 | B12: 46164 | C12: SERGIO | G12: =IFERROR(VLOOKUP(Tabla3[[#This Row],[NUM ECONOMICO]],MAQUINARIA!B:H,7,0), " MAQ") -> ACTIVA | H12: MM-02 | I12: 3F5108 | K12: 6 | M12: =+L12*K12 -> 0 | P12: =Tabla3[[#This Row],[COSTO UNITARIO DOLARES EN HAWTHORNE]]*Tabla3[[#This Row],[CANTIDAD SOLICTADA]] -> 0 | S12: =+Tabla3[[#This Row],[COSTO UNITARIO DOLARES CTP]]*Tabla3[[#This Row],[CANTIDAD SOLICTADA]] -> 0 | U12: CANCELADO | W12: 46164 | X12: SI | Y12: 7 | AE12: SE ENTREGARON SOLO 8 DE 4F3653 VER R-1666
A13: 3 | B13: 46164 | C13: SERGIO | G13: =IFERROR(VLOOKUP(Tabla3[[#This Row],[NUM ECONOMICO]],MAQUINARIA!B:H,7,0), " MAQ") -> ACTIVA | H13: MM-02 | I13: 4K0367 | K13: 6 | M13: =+L13*K13 -> 0 | P13: =Tabla3[[#This Row],[COSTO UNITARIO DOLARES EN HAWTHORNE]]*Tabla3[[#This Row],[CANTIDAD SOLICTADA]] -> 0 | S13: =+Tabla3[[#This Row],[COSTO UNITARIO DOLARES CTP]]*Tabla3[[#This Row],[CANTIDAD SOLICTADA]] -> 0 | U13: CANCELADO | W13: 46164 | X13: SI | Y13: 85 | AE13: SE ENTREGARON SOLO 8 DE 4F3653 VER R-1666
A14: 4 | B14: 46164 | C14: SERGIO | D14: CE-1421 | G14: =IFERROR(VLOOKUP(Tabla3[[#This Row],[NUM ECONOMICO]],MAQUINARIA!B:H,7,0), " MAQ") -> ACTIVA | H14: MC-04 | I14: 1781318 | K14: 1 | M14: =+L14*K14 -> 0 | P14: =Tabla3[[#This Row],[COSTO UNITARIO DOLARES EN HAWTHORNE]]*Tabla3[[#This Row],[CANTIDAD SOLICTADA]] -> 0 | S14: =+Tabla3[[#This Row],[COSTO UNITARIO DOLARES CTP]]*Tabla3[[#This Row],[CANTIDAD SOLICTADA]] -> 0 | U14: ENTREGADO | V14: QT-08-427536 | W14: 46168 | X14: NO | Y14: SIN EXISTENCIA | Z14: MATCO | AA14: 46167 | AB14: 46168 | AC14: EDUARDO CHOFER | AE14: SE ENTREGA EN OBRA
A15: 4 | B15: 46164 | C15: SERGIO | G15: =IFERROR(VLOOKUP(Tabla3[[#This Row],[NUM ECONOMICO]],MAQUINARIA!B:H,7,0), " MAQ") -> ACTIVA | H15: MC-04 | I15: 1917944 | K15: 1 | M15: =+L15*K15 -> 0 | P15: =Tabla3[[#This Row],[COSTO UNITARIO DOLARES EN HAWTHORNE]]*Tabla3[[#This Row],[CANTIDAD SOLICTADA]] -> 0 | S15: =+Tabla3[[#This Row],[COSTO UNITARIO DOLARES CTP]]*Tabla3[[#This Row],[CANTIDAD SOLICTADA]] -> 0 | U15: ENTREGADO | X15: SI | Y15: SIN EXISTENCIA | Z15: MATCO | AA15: 46167 | AB15: 46167 | AE15: PENDIENTE POR RECOGER SERGIO
A16: 5 | B16: 46164 | C16: JAVIER | G16: =IFERROR(VLOOKUP(Tabla3[[#This Row],[NUM ECONOMICO]],MAQUINARIA!B:H,7,0), " MAQ") -> ACTIVA | H16: ME-23 | I16: 4J8665 | K16: 2 | M16: =+L16*K16 -> 0 | P16: =Tabla3[[#This Row],[COSTO UNITARIO DOLARES EN HAWTHORNE]]*Tabla3[[#This Row],[CANTIDAD SOLICTADA]] -> 0 | S16: =+Tabla3[[#This Row],[COSTO UNITARIO DOLARES CTP]]*Tabla3[[#This Row],[CANTIDAD SOLICTADA]] -> 0 | U16: ENTREGADO | W16: 46164 | X16: SI | Y16: 0 | AC16: JAVIER G | AD16: R-1663
A17: 5 | B17: 46164 | C17: JAVIER | G17: =IFERROR(VLOOKUP(Tabla3[[#This Row],[NUM ECONOMICO]],MAQUINARIA!B:H,7,0), " MAQ") -> ACTIVA | H17: ME-23 | I17: 9W6092 | K17: 2 | M17: =+L17*K17 -> 0 | P17: =Tabla3[[#This Row],[COSTO UNITARIO DOLARES EN HAWTHORNE]]*Tabla3[[#This Row],[CANTIDAD SOLICTADA]] -> 0 | S17: =+Tabla3[[#This Row],[COSTO UNITARIO DOLARES CTP]]*Tabla3[[#This Row],[CANTIDAD SOLICTADA]] -> 0 | U17: ENTREGADO | W17: 46164 | X17: SI | Y17: 0 | AC17: JAVIER G | AD17: R-1663
A18: 5 | B18: 46164 | C18: JAVIER | G18: =IFERROR(VLOOKUP(Tabla3[[#This Row],[NUM ECONOMICO]],MAQUINARIA!B:H,7,0), " MAQ") -> ACTIVA | H18: ME-23 | I18: 4J9208 | K18: 32 | M18: =+L18*K18 -> 0 | P18: =Tabla3[[#This Row],[COSTO UNITARIO DOLARES EN HAWTHORNE]]*Tabla3[[#This Row],[CANTIDAD SOLICTADA]] -> 0 | S18: =+Tabla3[[#This Row],[COSTO UNITARIO DOLARES CTP]]*Tabla3[[#This Row],[CANTIDAD SOLICTADA]] -> 0 | U18: ENTREGADO | W18: 46164 | X18: SI | Y18: 0 | AC18: JAVIER G | AD18: R-1663
A19: 5 | B19: 46164 | C19: JAVIER | G19: =IFERROR(VLOOKUP(Tabla3[[#This Row],[NUM ECONOMICO]],MAQUINARIA!B:H,7,0), " MAQ") -> ACTIVA | H19: ME-23 | I19: 2J3507 | K19: 32 | M19: =+L19*K19 -> 0 | P19: =Tabla3[[#This Row],[COSTO UNITARIO DOLARES EN HAWTHORNE]]*Tabla3[[#This Row],[CANTIDAD SOLICTADA]] -> 0 | S19: =+Tabla3[[#This Row],[COSTO UNITARIO DOLARES CTP]]*Tabla3[[#This Row],[CANTIDAD SOLICTADA]] -> 0 | U19: ENTREGADO | W19: 46164 | X19: SI | Y19: 682 | AC19: JAVIER G | AD19: R-1663
A20: 6 | B20: 46164 | C20: JAVIER | G20: =IFERROR(VLOOKUP(Tabla3[[#This Row],[NUM ECONOMICO]],MAQUINARIA!B:H,7,0), " MAQ") -> ACTIVA | H20: ME-03 | I20: 4J9208 | K20: 22 | M20: =+L20*K20 -> 0 | P20: =Tabla3[[#This Row],[COSTO UNITARIO DOLARES EN HAWTHORNE]]*Tabla3[[#This Row],[CANTIDAD SOLICTADA]] -> 0 | S20: =+Tabla3[[#This Row],[COSTO UNITARIO DOLARES CTP]]*Tabla3[[#This Row],[CANTIDAD SOLICTADA]] -> 0 | U20: ENTREGADO | W20: 46164 | X20: SI | Y20: 0 | AC20: JAVIER G | AD20: R-1664
A21: 6 | B21: 46164 | C21: JAVIER | G21: =IFERROR(VLOOKUP(Tabla3[[#This Row],[NUM ECONOMICO]],MAQUINARIA!B:H,7,0), " MAQ") -> ACTIVA | H21: ME-03 | I21: 4J9208 | K21: 22 | M21: =+L21*K21 -> 0 | P21: =Tabla3[[#This Row],[COSTO UNITARIO DOLARES EN HAWTHORNE]]*Tabla3[[#This Row],[CANTIDAD SOLICTADA]] -> 0 | S21: =+Tabla3[[#This Row],[COSTO UNITARIO DOLARES CTP]]*Tabla3[[#This Row],[CANTIDAD SOLICTADA]] -> 0 | U21: ENTREGADO | W21: 46164 | X21: SI | Y21: 0 | AC21: JAVIER G | AD21: R-1664
A22: 7 | B22: 46164 | C22: JAVIER | G22: =IFERROR(VLOOKUP(Tabla3[[#This Row],[NUM ECONOMICO]],MAQUINARIA!B:H,7,0), " MAQ") -> ACTIVA | H22: MT-11 | I22: 4T5502 | K22: 2 | M22: =+L22*K22 -> 0 | P22: =Tabla3[[#This Row],[COSTO UNITARIO DOLARES EN HAWTHORNE]]*Tabla3[[#This Row],[CANTIDAD SOLICTADA]] -> 0 | S22: =+Tabla3[[#This Row],[COSTO UNITARIO DOLARES CTP]]*Tabla3[[#This Row],[CANTIDAD SOLICTADA]] -> 0 | U22: ENTREGADO | W22: 46164 | X22: SI | Y22: 0 | AC22: JAVIER G | AD22: R-1665
A23: 7 | B23: 46164 | C23: JAVIER | G23: =IFERROR(VLOOKUP(Tabla3[[#This Row],[NUM ECONOMICO]],MAQUINARIA!B:H,7,0), " MAQ") -> ACTIVA | H23: MT-11 | I23: 6Y1204 | K23: 2 | M23: =+L23*K23 -> 0 | P23: =Tabla3[[#This Row],[COSTO UNITARIO DOLARES EN HAWTHORNE]]*Tabla3[[#This Row],[CANTIDAD SOLICTADA]] -> 0 | S23: =+Tabla3[[#This Row],[COSTO UNITARIO DOLARES CTP]]*Tabla3[[#This Row],[CANTIDAD SOLICTADA]] -> 0 | U23: ENTREGADO | W23: 46164 | X23: SI | Y23: 15 | AC23: JAVIER G | AD23: R-1665
A24: 7 | B24: 46164 | C24: JAVIER | G24: =IFERROR(VLOOKUP(Tabla3[[#This Row],[NUM ECONOMICO]],MAQUINARIA!B:H,7,0), " MAQ") -> ACTIVA | H24: MT-11 | I24: 6Y1205 | K24: 2 | M24: =+L24*K24 -> 0 | P24: =Tabla3[[#This Row],[COSTO UNITARIO DOLARES EN HAWTHORNE]]*Tabla3[[#This Row],[CANTIDAD SOLICTADA]] -> 0 | S24: =+Tabla3[[#This Row],[COSTO UNITARIO DOLARES CTP]]*Tabla3[[#This Row],[CANTIDAD SOLICTADA]] -> 0 | U24: ENTREGADO | W24: 46164 | X24: SI | Y24: 0 | AC24: JAVIER G | AD24: R-1665
A25: 8 | B25: 46164 | C25: DAVID | G25: =IFERROR(VLOOKUP(Tabla3[[#This Row],[NUM ECONOMICO]],MAQUINARIA!B:H,7,0), " MAQ") -> ACTIVA | H25: MM-02 | I25: 4F3653 | K25: 8 | M25: =+L25*K25 -> 0 | P25: =Tabla3[[#This Row],[COSTO UNITARIO DOLARES EN HAWTHORNE]]*Tabla3[[#This Row],[CANTIDAD SOLICTADA]] -> 0 | S25: =+Tabla3[[#This Row],[COSTO UNITARIO DOLARES CTP]]*Tabla3[[#This Row],[CANTIDAD SOLICTADA]] -> 0 | U25: ENTREGADO | W25: 46164 | X25: SI | Y25: SIN EXISTENCIA | AC25: DAVID | AD25: R-1666
A26: 9 | B26: 46164 | C26: SERGIO | G26: =IFERROR(VLOOKUP(Tabla3[[#This Row],[NUM ECONOMICO]],MAQUINARIA!B:H,7,0), " MAQ") -> ACTIVA | H26: ME-32 | I26: 1997954 | K26: 1 | M26: =+L26*K26 -> 0 | P26: =Tabla3[[#This Row],[COSTO UNITARIO DOLARES EN HAWTHORNE]]*Tabla3[[#This Row],[CANTIDAD SOLICTADA]] -> 0 | S26: =+Tabla3[[#This Row],[COSTO UNITARIO DOLARES CTP]]*Tabla3[[#This Row],[CANTIDAD SOLICTADA]] -> 0 | U26: ENTREGADO | W26: 46164 | X26: SI | Y26: 3 | AC26: SERGIO | AD26: R-1667
A27: 10 | B27: 46164 | C27: SERGIO | D27: CE-1423 | G27: =IFERROR(VLOOKUP(Tabla3[[#This Row],[NUM ECONOMICO]],MAQUINARIA!B:H,7,0), " MAQ") -> ACTIVA | H27: MT-03 | I27: 5P7593 | K27: 1 | M27: =+L27*K27 -> 0 | P27: =Tabla3[[#This Row],[COSTO UNITARIO DOLARES EN HAWTHORNE]]*Tabla3[[#This Row],[CANTIDAD SOLICTADA]] -> 0 | S27: =+Tabla3[[#This Row],[COSTO UNITARIO DOLARES CTP]]*Tabla3[[#This Row],[CANTIDAD SOLICTADA]] -> 0 | U27: ENTREGADO | V27: QT-08-427384 | W27: 46169 | X27: NO | Y27: SIN EXISTENCIA | Z27: MATCO | AA27: 46168 | AB27: 46169 | AE27: CONFIRMA SERGIO ENTREGA
A28: 10 | B28: 46164 | C28: SERGIO | D28: CE-1423 | G28: =IFERROR(VLOOKUP(Tabla3[[#This Row],[NUM ECONOMICO]],MAQUINARIA!B:H,7,0), " MAQ") -> ACTIVA | H28: MT-03 | I28: 1U1738 | K28: 1 | M28: =+L28*K28 -> 0 | P28: =Tabla3[[#This Row],[COSTO UNITARIO DOLARES EN HAWTHORNE]]*Tabla3[[#This Row],[CANTIDAD SOLICTADA]] -> 0 | S28: =+Tabla3[[#This Row],[COSTO UNITARIO DOLARES CTP]]*Tabla3[[#This Row],[CANTIDAD SOLICTADA]] -> 0 | U28: ENTREGADO | V28: QT-08-427384 | W28: 46169 | X28: NO | Y28: SIN EXISTENCIA | Z28: MATCO | AA28: 46168 | AB28: 46169 | AE28: CONFIRMA SERGIO ENTREGA
A29: 11 | B29: 46167 | C29: SERGIO | D29: CE-1416 | G29: =IFERROR(VLOOKUP(Tabla3[[#This Row],[NUM ECONOMICO]],MAQUINARIA!B:H,7,0), " MAQ") -> INACTIVA | H29: ME-16 | I29: 1015459 | K29: 1 | M29: =+L29*K29 -> 0 | P29: =Tabla3[[#This Row],[COSTO UNITARIO DOLARES EN HAWTHORNE]]*Tabla3[[#This Row],[CANTIDAD SOLICTADA]] -> 0 | S29: =+Tabla3[[#This Row],[COSTO UNITARIO DOLARES CTP]]*Tabla3[[#This Row],[CANTIDAD SOLICTADA]] -> 0 | U29: ENTREGADO | W29: 46174 | X29: NO | Y29: SIN EXISTENCIA | Z29: MATCO | AA29: 46167 | AB29: 46170 | AC29: CHOFER EDUARDO | AE29: SE ENTREGA A JAVIER
A30: 12 | B30: 46167 | C30: SERGIO | E30: 20 | F30: 46178 | G30: =IFERROR(VLOOKUP(Tabla3[[#This Row],[NUM ECONOMICO]],MAQUINARIA!B:H,7,0), " MAQ") -> INACTIVA | H30: ME-28 | I30: 5L8854 | K30: 2 | M30: =+L30*K30 -> 0 | P30: =Tabla3[[#This Row],[COSTO UNITARIO DOLARES EN HAWTHORNE]]*Tabla3[[#This Row],[CANTIDAD SOLICTADA]] -> 0 | S30: =+Tabla3[[#This Row],[COSTO UNITARIO DOLARES CTP]]*Tabla3[[#This Row],[CANTIDAD SOLICTADA]] -> 0 | U30: ENTREGADO | W30: 46191 | X30: SI | Y30: 3 | AC30: SERGIO | AE30: SE ENTREGA A SERGIO | AG30: SILENCIADOR
A31: 12 | B31: 46167 | C31: SERGIO | E31: 20 | F31: 46178 | G31: =IFERROR(VLOOKUP(Tabla3[[#This Row],[NUM ECONOMICO]],MAQUINARIA!B:H,7,0), " MAQ") -> INACTIVA | H31: ME-28 | I31: 9N1941 | K31: 1 | M31: =+L31*K31 -> 0 | P31: =Tabla3[[#This Row],[COSTO UNITARIO DOLARES EN HAWTHORNE]]*Tabla3[[#This Row],[CANTIDAD SOLICTADA]] -> 0 | S31: =+Tabla3[[#This Row],[COSTO UNITARIO DOLARES CTP]]*Tabla3[[#This Row],[CANTIDAD SOLICTADA]] -> 0 | U31: ENTREGADO | W31: 46191 | X31: SI | Y31: 1 | AC31: SERGIO | AE31: SE ENTREGA A SERGIO | AG31: SILENCIADOR
A32: 12 | B32: 46167 | C32: SERGIO | E32: 20 | F32: 46178 | G32: =IFERROR(VLOOKUP(Tabla3[[#This Row],[NUM ECONOMICO]],MAQUINARIA!B:H,7,0), " MAQ") -> INACTIVA | H32: ME-28 | I32: 1752931 | K32: 1 | L32: 34307.69 | M32: =+L32*K32 -> 34307.69 | P32: =Tabla3[[#This Row],[COSTO UNITARIO DOLARES EN HAWTHORNE]]*Tabla3[[#This Row],[CANTIDAD SOLICTADA]] -> 0 | S32: =+Tabla3[[#This Row],[COSTO UNITARIO DOLARES CTP]]*Tabla3[[#This Row],[CANTIDAD SOLICTADA]] -> 0 | U32: ENTREGADO | V32: QT-08-427469 | W32: 46191 | X32: NO | Y32: SIN EXISTENCIA | AE32: BENJA | AG32: SILENCIADOR
A33: 13 | B33: 46167 | C33: SERGIO | G33: =IFERROR(VLOOKUP(Tabla3[[#This Row],[NUM ECONOMICO]],MAQUINARIA!B:H,7,0), " MAQ") -> ACTIVA | H33: ME-14 | I33: 2N2765 | K33: 4 | M33: =+L33*K33 -> 0 | P33: =Tabla3[[#This Row],[COSTO UNITARIO DOLARES EN HAWTHORNE]]*Tabla3[[#This Row],[CANTIDAD SOLICTADA]] -> 0 | S33: =+Tabla3[[#This Row],[COSTO UNITARIO DOLARES CTP]]*Tabla3[[#This Row],[CANTIDAD SOLICTADA]] -> 0 | U33: ENTREGADO | W33: 46167 | X33: SI | Y33: 32 | AC33: SERGIO | AD33: R-1673
A34: 14 | B34: 46167 | C34: SERGIO | G34: =IFERROR(VLOOKUP(Tabla3[[#This Row],[NUM ECONOMICO]],MAQUINARIA!B:H,7,0), " MAQ") -> ACTIVA | H34: ME-14 | I34: 2N2766 | J34: TUBERÍA A | K34: 4 | M34: =+L34*K34 -> 0 | P34: =Tabla3[[#This Row],[COSTO UNITARIO DOLARES EN HAWTHORNE]]*Tabla3[[#This Row],[CANTIDAD SOLICTADA]] -> 0 | R34: 0.82 | S34: =+Tabla3[[#This Row],[COSTO UNITARIO DOLARES CTP]]*Tabla3[[#This Row],[CANTIDAD SOLICTADA]] -> 3.28 | U34: ENTREGADO | W34: 46167 | X34: SI | Y34: 6 | AC34: SERGIO | AD34: R-1673
A35: 15 | B35: 46167 | C35: SERGIO | G35: =IFERROR(VLOOKUP(Tabla3[[#This Row],[NUM ECONOMICO]],MAQUINARIA!B:H,7,0), " MAQ") -> ACTIVA | H35: ME-14 | I35: 1S4295 | J35: PUMP GR - GEAR FU | K35: 1 | M35: =+L35*K35 -> 0 | P35: =Tabla3[[#This Row],[COSTO UNITARIO DOLARES EN HAWTHORNE]]*Tabla3[[#This Row],[CANTIDAD SOLICTADA]] -> 0 | R35: 3.98 | S35: =+Tabla3[[#This Row],[COSTO UNITARIO DOLARES CTP]]*Tabla3[[#This Row],[CANTIDAD SOLICTADA]] -> 3.98 | U35: ENTREGADO | W35: 46167 | X35: SI | Y35: 22 | AC35: SERGIO | AD35: R-1673
A36: 16 | B36: 46167 | C36: SERGIO | D36: CE-1417 | G36: =IFERROR(VLOOKUP(Tabla3[[#This Row],[NUM ECONOMICO]],MAQUINARIA!B:H,7,0), " MAQ") -> ACTIVA | H36: ME-14 | I36: 9N2038 | K36: 1 | M36: =+L36*K36 -> 0 | P36: =Tabla3[[#This Row],[COSTO UNITARIO DOLARES EN HAWTHORNE]]*Tabla3[[#This Row],[CANTIDAD SOLICTADA]] -> 0 | S36: =+Tabla3[[#This Row],[COSTO UNITARIO DOLARES CTP]]*Tabla3[[#This Row],[CANTIDAD SOLICTADA]] -> 0 | U36: ENTREGADO | W36: 46167 | X36: NO | Y36: 0 | Z36: TDR | AA36: 46167 | AB36: 46167 | AC36: SERGIO
A37: 17 | B37: 46167 | C37: SERGIO | G37: =IFERROR(VLOOKUP(Tabla3[[#This Row],[NUM ECONOMICO]],MAQUINARIA!B:H,7,0), " MAQ") -> ACTIVA | H37: MT-08 | I37: 8T8927 | K37: 16 | M37: =+L37*K37 -> 0 | P37: =Tabla3[[#This Row],[COSTO UNITARIO DOLARES EN HAWTHORNE]]*Tabla3[[#This Row],[CANTIDAD SOLICTADA]] -> 0 | S37: =+Tabla3[[#This Row],[COSTO UNITARIO DOLARES CTP]]*Tabla3[[#This Row],[CANTIDAD SOLICTADA]] -> 0 | U37: ENTREGADO | V37: QT-08-427546 | X37: NO | Y37: SIN EXISTENCIA
A38: 17 | B38: 46167 | C38: SERGIO | G38: =IFERROR(VLOOKUP(Tabla3[[#This Row],[NUM ECONOMICO]],MAQUINARIA!B:H,7,0), " MAQ") -> ACTIVA | H38: MT-08 | I38: 8T5361 | K38: 16 | M38: =+L38*K38 -> 0 | P38: =Tabla3[[#This Row],[COSTO UNITARIO DOLARES EN HAWTHORNE]]*Tabla3[[#This Row],[CANTIDAD SOLICTADA]] -> 0 | S38: =+Tabla3[[#This Row],[COSTO UNITARIO DOLARES CTP]]*Tabla3[[#This Row],[CANTIDAD SOLICTADA]] -> 0 | U38: EN ALMACEN | X38: SI | Y38: 32 | XFD38: =+Tabla3[[#This Row],[ESTATUS DE NUM ECONOMICO]] -> ACTIVA
A39: 17 | B39: 46167 | C39: SERGIO | G39: =IFERROR(VLOOKUP(Tabla3[[#This Row],[NUM ECONOMICO]],MAQUINARIA!B:H,7,0), " MAQ") -> ACTIVA | H39: MT-08 | I39: 7M0475 | K39: 1 | M39: =+L39*K39 -> 0 | P39: =Tabla3[[#This Row],[COSTO UNITARIO DOLARES EN HAWTHORNE]]*Tabla3[[#This Row],[CANTIDAD SOLICTADA]] -> 0 | S39: =+Tabla3[[#This Row],[COSTO UNITARIO DOLARES CTP]]*Tabla3[[#This Row],[CANTIDAD SOLICTADA]] -> 0 | U39: ENTREGADO | V39: QT-08-427546 | X39: NO | Y39: 1 | XFD39: =+Tabla3[[#This Row],[ESTATUS DE NUM ECONOMICO]] -> ACTIVA
A40: 17 | B40: 46167 | C40: SERGIO | G40: =IFERROR(VLOOKUP(Tabla3[[#This Row],[NUM ECONOMICO]],MAQUINARIA!B:H,7,0), " MAQ") -> ACTIVA | H40: MT-08 | I40: 2160273 | K40: 1 | M40: =+L40*K40 -> 0 | P40: =Tabla3[[#This Row],[COSTO UNITARIO DOLARES EN HAWTHORNE]]*Tabla3[[#This Row],[CANTIDAD SOLICTADA]] -> 0 | S40: =+Tabla3[[#This Row],[COSTO UNITARIO DOLARES CTP]]*Tabla3[[#This Row],[CANTIDAD SOLICTADA]] -> 0 | U40: ENTREGADO | V40: QT-08-427546 | X40: NO | Y40: 1 | XFD40: =+Tabla3[[#This Row],[ESTATUS DE NUM ECONOMICO]] -> ACTIVA
...

Sheet RESUMEN GLOBAL
B2: COMPARATIVO DE COTIZACIÓN DE REFACCIONES — 2026
B3: TIPO DE CAMBIO DEL DÍA (MXN/USD): | E3: 17 | F3: ⬅ Captura aquí el tipo de cambio del día
B5: RESUMEN GLOBAL — PARTIDAS EN COTIZACIÓN (Excluye Servicios de Filtros) | N5: Proveedor | O5: Costo MXN
B6: Unidades con pedidos | C6: Pedidos en cotización | D6: Partidas totales | E6: Costo total MATCO (MXN s/IVA) | F6: Costo total HAWTHORNE (USD) | G6: Costo total CTP (USD) | H6: Partidas con costo MATCO | I6: Sin precio MATCO | J6: Partidas cotizadas HAWTHORNE | K6: Partidas cotizadas CTP | N6: MATCO | O6: =E8 -> 6047672
B7: {=ROWS(_xlfn.UNIQUE(_xlfn._xlws.FILTER(Tabla3[NUM ECONOMICO],(Tabla3[STATUS]="COTIZANDO")*(Tabla3[TEMA]<>"SERVICIO DE FILTROS"))))} -> 13 | C7: {=ROWS(_xlfn.UNIQUE(_xlfn._xlws.FILTER(Tabla3[PEDIDO],(Tabla3[STATUS]="COTIZANDO")*(Tabla3[TEMA]<>"SERVICIO DE FILTROS"))))} -> 18 | D7: =COUNTIFS(Tabla3[STATUS],"COTIZANDO",Tabla3[TEMA],"<>SERVICIO DE FILTROS") -> 704 | E7: =SUMIFS(Tabla3[COSTO TOTAL SIN IVA PESOS EN MATCO],Tabla3[STATUS],"COTIZANDO",Tabla3[TEMA],"<>SERVICIO DE FILTROS") -> 6047672 | F7: =SUMIFS(Tabla3[COSTO TOTAL DOLARES EN HAWTHORNE],Tabla3[STATUS],"COTIZANDO",Tabla3[TEMA],"<>SERVICIO DE FILTROS") -> 191410.88 | G7: =SUMIFS(Tabla3[COSTO TOTAL DOLARES CTP],Tabla3[STATUS],"COTIZANDO",Tabla3[TEMA],"<>SERVICIO DE FILTROS") -> 23109.76 | H7: =COUNTIFS(Tabla3[STATUS],"COTIZANDO",Tabla3[COSTO TOTAL SIN IVA PESOS EN MATCO],">0",Tabla3[TEMA],"<>SERVICIO DE FILTROS") -> 699 | I7: =COUNTIFS(Tabla3[STATUS],"COTIZANDO",Tabla3[COSTO TOTAL SIN IVA PESOS EN MATCO],"=0",Tabla3[TEMA],"<>SERVICIO DE FILTROS") -> 5 | J7: =COUNTIFS(Tabla3[STATUS],"COTIZANDO",Tabla3[COSTO TOTAL DOLARES EN HAWTHORNE],">0",Tabla3[TEMA],"<>SERVICIO DE FILTROS") -> 190 | K7: =COUNTIFS(Tabla3[STATUS],"COTIZANDO",Tabla3[COSTO TOTAL DOLARES CTP],">0",Tabla3[TEMA],"<>SERVICIO DE FILTROS") -> 153 | N7: HAWTHORNE | O7: =F8 -> 3253985
D8: Costo equivalente en MXN | E8: =E7 -> 6047672 | F8: =IF($E$3>0,F7*$E$3,0) -> 3253985 | G8: =IF($E$3>0,G7*$E$3,0) -> 392865.92 | N8: CTP | O8: =G8 -> 392865.92
B10: RESUMEN POR UNIDAD ECONÓMICA (Excluye Servicios de Filtros)
B11: NÚM. ECON. | C11: ESTATUS | D11: FAMILIA / MODELO | E11: PEDIDOS | F11: PARTIDAS | G11: COSTO MATCO (MXN s/IVA) | H11: COSTO HAWTHORNE (USD) | I11: HAWTHORNE EN MXN * | J11: COSTO CTP (USD) | K11: CTP EN MXN * | L11: DÍAS MATCO
B12: =MAQUINARIA!B421 -> BC-01 | C12: =MAQUINARIA!H421 -> ACTIVA | D12: =IFERROR(TRIM(MAQUINARIA!C421&" "&MAQUINARIA!E421),"—") -> BOMBA DE CONCRETO | E12: {=IF(B12="",0,IFERROR(ROWS(_xlfn.UNIQUE(_xlfn._xlws.FILTER(Tabla3[PEDIDO],(Tabla3[STATUS]="COTIZANDO")*(Tabla3[NUM ECONOMICO]=B12)*(Tabla3[TEMA]<>"SERVICIO DE FILTROS")))),0))} -> 0 | F12: =IF(B12="",0,COUNTIFS(Tabla3[STATUS],"COTIZANDO",Tabla3[NUM ECONOMICO],B12,Tabla3[TEMA],"<>SERVICIO DE FILTROS")) -> 0 | G12: =IF(B12="",0,SUMIFS(Tabla3[COSTO TOTAL SIN IVA PESOS EN MATCO],Tabla3[STATUS],"COTIZANDO",Tabla3[NUM ECONOMICO],B12,Tabla3[TEMA],"<>SERVICIO DE FILTROS")) -> 0 | H12: =IF(B12="",0,SUMIFS(Tabla3[COSTO TOTAL DOLARES EN HAWTHORNE],Tabla3[STATUS],"COTIZANDO",Tabla3[NUM ECONOMICO],B12,Tabla3[TEMA],"<>SERVICIO DE FILTROS")) -> 0 | I12: =IF(B12="","",_xlfn.LET(_xlpm.totalUSD,SUMIFS(Tabla3[COSTO TOTAL DOLARES EN HAWTHORNE],Tabla3[STATUS],"COTIZANDO",Tabla3[NUM ECONOMICO],B12,Tabla3[TEMA],"<>SERVICIO DE FILTROS"),IF(OR(TC="",_xlpm.totalUSD=0),"—",_xlpm.totalUSD*TC))) -> — | J12: =IF(B12="",0,SUMIFS(Tabla3[COSTO TOTAL DOLARES CTP],Tabla3[STATUS],"COTIZANDO",Tabla3[NUM ECONOMICO],B12,Tabla3[TEMA],"<>SERVICIO DE FILTROS")) -> 0 | K12: =IF(B12="","",_xlfn.LET(_xlpm.totalUSD,SUMIFS(Tabla3[COSTO TOTAL DOLARES CTP],Tabla3[STATUS],"COTIZANDO",Tabla3[NUM ECONOMICO],B12,Tabla3[TEMA],"<>SERVICIO DE FILTROS"),IF(OR(TC="",_xlpm.totalUSD=0),"—",_xlpm.totalUSD*TC))) -> — | L12: {=IF(B12="",0,IFERROR(MAX(_xlfn._xlws.FILTER(Tabla3[DIAS DE ENTREGA TENTATIVO EN MATCO],(Tabla3[STATUS]="COTIZANDO")*(Tabla3[NUM ECONOMICO]=B12)*(Tabla3[TEMA]<>"SERVICIO DE FILTROS"))),0))} -> 0
B13: =MAQUINARIA!B462 -> CGP-01 | C13: =MAQUINARIA!H462 -> ACTIVA | D13: =IFERROR(TRIM(MAQUINARIA!C462&" "&MAQUINARIA!E462),"—") -> CAMION GRUA PERFORADOR | E13: {=IF(B13="",0,IFERROR(ROWS(_xlfn.UNIQUE(_xlfn._xlws.FILTER(Tabla3[PEDIDO],(Tabla3[STATUS]="COTIZANDO")*(Tabla3[NUM ECONOMICO]=B13)*(Tabla3[TEMA]<>"SERVICIO DE FILTROS")))),0))} -> 0 | F13: =IF(B13="",0,COUNTIFS(Tabla3[STATUS],"COTIZANDO",Tabla3[NUM ECONOMICO],B13,Tabla3[TEMA],"<>SERVICIO DE FILTROS")) -> 0 | G13: =IF(B13="",0,SUMIFS(Tabla3[COSTO TOTAL SIN IVA PESOS EN MATCO],Tabla3[STATUS],"COTIZANDO",Tabla3[NUM ECONOMICO],B13,Tabla3[TEMA],"<>SERVICIO DE FILTROS")) -> 0 | H13: =IF(B13="",0,SUMIFS(Tabla3[COSTO TOTAL DOLARES EN HAWTHORNE],Tabla3[STATUS],"COTIZANDO",Tabla3[NUM ECONOMICO],B13,Tabla3[TEMA],"<>SERVICIO DE FILTROS")) -> 0 | I13: =IF(B13="","",_xlfn.LET(_xlpm.totalUSD,SUMIFS(Tabla3[COSTO TOTAL DOLARES EN HAWTHORNE],Tabla3[STATUS],"COTIZANDO",Tabla3[NUM ECONOMICO],B13,Tabla3[TEMA],"<>SERVICIO DE FILTROS"),IF(OR(TC="",_xlpm.totalUSD=0),"—",_xlpm.totalUSD*TC))) -> — | J13: =IF(B13="",0,SUMIFS(Tabla3[COSTO TOTAL DOLARES CTP],Tabla3[STATUS],"COTIZANDO",Tabla3[NUM ECONOMICO],B13,Tabla3[TEMA],"<>SERVICIO DE FILTROS")) -> 0 | K13: =IF(B13="","",_xlfn.LET(_xlpm.totalUSD,SUMIFS(Tabla3[COSTO TOTAL DOLARES CTP],Tabla3[STATUS],"COTIZANDO",Tabla3[NUM ECONOMICO],B13,Tabla3[TEMA],"<>SERVICIO DE FILTROS"),IF(OR(TC="",_xlpm.totalUSD=0),"—",_xlpm.totalUSD*TC))) -> — | L13: {=IF(B13="",0,IFERROR(MAX(_xlfn._xlws.FILTER(Tabla3[DIAS DE ENTREGA TENTATIVO EN MATCO],(Tabla3[STATUS]="COTIZANDO")*(Tabla3[NUM ECONOMICO]=B13)*(Tabla3[TEMA]<>"SERVICIO DE FILTROS"))),0))} -> 0
B14: =MAQUINARIA!B493 -> CL-01 | C14: =MAQUINARIA!H493 -> INACTIVA | D14: =IFERROR(TRIM(MAQUINARIA!C493&" "&MAQUINARIA!E493),"—") -> CAMION DE LAVADO 650 | E14: {=IF(B14="",0,IFERROR(ROWS(_xlfn.UNIQUE(_xlfn._xlws.FILTER(Tabla3[PEDIDO],(Tabla3[STATUS]="COTIZANDO")*(Tabla3[NUM ECONOMICO]=B14)*(Tabla3[TEMA]<>"SERVICIO DE FILTROS")))),0))} -> 0 | F14: =IF(B14="",0,COUNTIFS(Tabla3[STATUS],"COTIZANDO",Tabla3[NUM ECONOMICO],B14,Tabla3[TEMA],"<>SERVICIO DE FILTROS")) -> 0 | G14: =IF(B14="",0,SUMIFS(Tabla3[COSTO TOTAL SIN IVA PESOS EN MATCO],Tabla3[STATUS],"COTIZANDO",Tabla3[NUM ECONOMICO],B14,Tabla3[TEMA],"<>SERVICIO DE FILTROS")) -> 0 | H14: =IF(B14="",0,SUMIFS(Tabla3[COSTO TOTAL DOLARES EN HAWTHORNE],Tabla3[STATUS],"COTIZANDO",Tabla3[NUM ECONOMICO],B14,Tabla3[TEMA],"<>SERVICIO DE FILTROS")) -> 0 | I14: =IF(B14="","",_xlfn.LET(_xlpm.totalUSD,SUMIFS(Tabla3[COSTO TOTAL DOLARES EN HAWTHORNE],Tabla3[STATUS],"COTIZANDO",Tabla3[NUM ECONOMICO],B14,Tabla3[TEMA],"<>SERVICIO DE FILTROS"),IF(OR(TC="",_xlpm.totalUSD=0),"—",_xlpm.totalUSD*TC))) -> — | J14: =IF(B14="",0,SUMIFS(Tabla3[COSTO TOTAL DOLARES CTP],Tabla3[STATUS],"COTIZANDO",Tabla3[NUM ECONOMICO],B14,Tabla3[TEMA],"<>SERVICIO DE FILTROS")) -> 0 | K14: =IF(B14="","",_xlfn.LET(_xlpm.totalUSD,SUMIFS(Tabla3[COSTO TOTAL DOLARES CTP],Tabla3[STATUS],"COTIZANDO",Tabla3[NUM ECONOMICO],B14,Tabla3[TEMA],"<>SERVICIO DE FILTROS"),IF(OR(TC="",_xlpm.totalUSD=0),"—",_xlpm.totalUSD*TC))) -> — | L14: {=IF(B14="",0,IFERROR(MAX(_xlfn._xlws.FILTER(Tabla3[DIAS DE ENTREGA TENTATIVO EN MATCO],(Tabla3[STATUS]="COTIZANDO")*(Tabla3[NUM ECONOMICO]=B14)*(Tabla3[TEMA]<>"SERVICIO DE FILTROS"))),0))} -> 0
B15: =MAQUINARIA!B481 -> CM-01 | C15: =MAQUINARIA!H481 -> ACTIVA | D15: =IFERROR(TRIM(MAQUINARIA!C481&" "&MAQUINARIA!E481),"—") -> CAMA BAJA | E15: {=IF(B15="",0,IFERROR(ROWS(_xlfn.UNIQUE(_xlfn._xlws.FILTER(Tabla3[PEDIDO],(Tabla3[STATUS]="COTIZANDO")*(Tabla3[NUM ECONOMICO]=B15)*(Tabla3[TEMA]<>"SERVICIO DE FILTROS")))),0))} -> 0 | F15: =IF(B15="",0,COUNTIFS(Tabla3[STATUS],"COTIZANDO",Tabla3[NUM ECONOMICO],B15,Tabla3[TEMA],"<>SERVICIO DE FILTROS")) -> 0 | G15: =IF(B15="",0,SUMIFS(Tabla3[COSTO TOTAL SIN IVA PESOS EN MATCO],Tabla3[STATUS],"COTIZANDO",Tabla3[NUM ECONOMICO],B15,Tabla3[TEMA],"<>SERVICIO DE FILTROS")) -> 0 | H15: =IF(B15="",0,SUMIFS(Tabla3[COSTO TOTAL DOLARES EN HAWTHORNE],Tabla3[STATUS],"COTIZANDO",Tabla3[NUM ECONOMICO],B15,Tabla3[TEMA],"<>SERVICIO DE FILTROS")) -> 0 | I15: =IF(B15="","",_xlfn.LET(_xlpm.totalUSD,SUMIFS(Tabla3[COSTO TOTAL DOLARES EN HAWTHORNE],Tabla3[STATUS],"COTIZANDO",Tabla3[NUM ECONOMICO],B15,Tabla3[TEMA],"<>SERVICIO DE FILTROS"),IF(OR(TC="",_xlpm.totalUSD=0),"—",_xlpm.totalUSD*TC))) -> — | J15: =IF(B15="",0,SUMIFS(Tabla3[COSTO TOTAL DOLARES CTP],Tabla3[STATUS],"COTIZANDO",Tabla3[NUM ECONOMICO],B15,Tabla3[TEMA],"<>SERVICIO DE FILTROS")) -> 0 | K15: =IF(B15="","",_xlfn.LET(_xlpm.totalUSD,SUMIFS(Tabla3[COSTO TOTAL DOLARES CTP],Tabla3[STATUS],"COTIZANDO",Tabla3[NUM ECONOMICO],B15,Tabla3[TEMA],"<>SERVICIO DE FILTROS"),IF(OR(TC="",_xlpm.totalUSD=0),"—",_xlpm.totalUSD*TC))) -> — | L15: {=IF(B15="",0,IFERROR(MAX(_xlfn._xlws.FILTER(Tabla3[DIAS DE ENTREGA TENTATIVO EN MATCO],(Tabla3[STATUS]="COTIZANDO")*(Tabla3[NUM ECONOMICO]=B15)*(Tabla3[TEMA]<>"SERVICIO DE FILTROS"))),0))} -> 0
B16: =MAQUINARIA!B482 -> CM-02 | C16: =MAQUINARIA!H482 -> ACTIVA | D16: =IFERROR(TRIM(MAQUINARIA!C482&" "&MAQUINARIA!E482),"—") -> CAMA BAJA WITZCO | E16: {=IF(B16="",0,IFERROR(ROWS(_xlfn.UNIQUE(_xlfn._xlws.FILTER(Tabla3[PEDIDO],(Tabla3[STATUS]="COTIZANDO")*(Tabla3[NUM ECONOMICO]=B16)*(Tabla3[TEMA]<>"SERVICIO DE FILTROS")))),0))} -> 0 | F16: =IF(B16="",0,COUNTIFS(Tabla3[STATUS],"COTIZANDO",Tabla3[NUM ECONOMICO],B16,Tabla3[TEMA],"<>SERVICIO DE FILTROS")) -> 0 | G16: =IF(B16="",0,SUMIFS(Tabla3[COSTO TOTAL SIN IVA PESOS EN MATCO],Tabla3[STATUS],"COTIZANDO",Tabla3[NUM ECONOMICO],B16,Tabla3[TEMA],"<>SERVICIO DE FILTROS")) -> 0 | H16: =IF(B16="",0,SUMIFS(Tabla3[COSTO TOTAL DOLARES EN HAWTHORNE],Tabla3[STATUS],"COTIZANDO",Tabla3[NUM ECONOMICO],B16,Tabla3[TEMA],"<>SERVICIO DE FILTROS")) -> 0 | I16: =IF(B16="","",_xlfn.LET(_xlpm.totalUSD,SUMIFS(Tabla3[COSTO TOTAL DOLARES EN HAWTHORNE],Tabla3[STATUS],"COTIZANDO",Tabla3[NUM ECONOMICO],B16,Tabla3[TEMA],"<>SERVICIO DE FILTROS"),IF(OR(TC="",_xlpm.totalUSD=0),"—",_xlpm.totalUSD*TC))) -> — | J16: =IF(B16="",0,SUMIFS(Tabla3[COSTO TOTAL DOLARES CTP],Tabla3[STATUS],"COTIZANDO",Tabla3[NUM ECONOMICO],B16,Tabla3[TEMA],"<>SERVICIO DE FILTROS")) -> 0 | K16: =IF(B16="","",_xlfn.LET(_xlpm.totalUSD,SUMIFS(Tabla3[COSTO TOTAL DOLARES CTP],Tabla3[STATUS],"COTIZANDO",Tabla3[NUM ECONOMICO],B16,Tabla3[TEMA],"<>SERVICIO DE FILTROS"),IF(OR(TC="",_xlpm.totalUSD=0),"—",_xlpm.totalUSD*TC))) -> — | L16: {=IF(B16="",0,IFERROR(MAX(_xlfn._xlws.FILTER(Tabla3[DIAS DE ENTREGA TENTATIVO EN MATCO],(Tabla3[STATUS]="COTIZANDO")*(Tabla3[NUM ECONOMICO]=B16)*(Tabla3[TEMA]<>"SERVICIO DE FILTROS"))),0))} -> 0
B17: =MAQUINARIA!B483 -> CM-03 | C17: =MAQUINARIA!H483 -> ACTIVA | D17: =IFERROR(TRIM(MAQUINARIA!C483&" "&MAQUINARIA!E483),"—") -> CAMA BAJA | E17: {=IF(B17="",0,IFERROR(ROWS(_xlfn.UNIQUE(_xlfn._xlws.FILTER(Tabla3[PEDIDO],(Tabla3[STATUS]="COTIZANDO")*(Tabla3[NUM ECONOMICO]=B17)*(Tabla3[TEMA]<>"SERVICIO DE FILTROS")))),0))} -> 0 | F17: =IF(B17="",0,COUNTIFS(Tabla3[STATUS],"COTIZANDO",Tabla3[NUM ECONOMICO],B17,Tabla3[TEMA],"<>SERVICIO DE FILTROS")) -> 0 | G17: =IF(B17="",0,SUMIFS(Tabla3[COSTO TOTAL SIN IVA PESOS EN MATCO],Tabla3[STATUS],"COTIZANDO",Tabla3[NUM ECONOMICO],B17,Tabla3[TEMA],"<>SERVICIO DE FILTROS")) -> 0 | H17: =IF(B17="",0,SUMIFS(Tabla3[COSTO TOTAL DOLARES EN HAWTHORNE],Tabla3[STATUS],"COTIZANDO",Tabla3[NUM ECONOMICO],B17,Tabla3[TEMA],"<>SERVICIO DE FILTROS")) -> 0 | I17: =IF(B17="","",_xlfn.LET(_xlpm.totalUSD,SUMIFS(Tabla3[COSTO TOTAL DOLARES EN HAWTHORNE],Tabla3[STATUS],"COTIZANDO",Tabla3[NUM ECONOMICO],B17,Tabla3[TEMA],"<>SERVICIO DE FILTROS"),IF(OR(TC="",_xlpm.totalUSD=0),"—",_xlpm.totalUSD*TC))) -> — | J17: =IF(B17="",0,SUMIFS(Tabla3[COSTO TOTAL DOLARES CTP],Tabla3[STATUS],"COTIZANDO",Tabla3[NUM ECONOMICO],B17,Tabla3[TEMA],"<>SERVICIO DE FILTROS")) -> 0 | K17: =IF(B17="","",_xlfn.LET(_xlpm.totalUSD,SUMIFS(Tabla3[COSTO TOTAL DOLARES CTP],Tabla3[STATUS],"COTIZANDO",Tabla3[NUM ECONOMICO],B17,Tabla3[TEMA],"<>SERVICIO DE FILTROS"),IF(OR(TC="",_xlpm.totalUSD=0),"—",_xlpm.totalUSD*TC))) -> — | L17: {=IF(B17="",0,IFERROR(MAX(_xlfn._xlws.FILTER(Tabla3[DIAS DE ENTREGA TENTATIVO EN MATCO],(Tabla3[STATUS]="COTIZANDO")*(Tabla3[NUM ECONOMICO]=B17)*(Tabla3[TEMA]<>"SERVICIO DE FILTROS"))),0))} -> 0
B18: =MAQUINARIA!B484 -> CM-04 | C18: =MAQUINARIA!H484 -> INACTIVA | D18: =IFERROR(TRIM(MAQUINARIA!C484&" "&MAQUINARIA!E484),"—") -> CAMA BAJA DOLLY | E18: {=IF(B18="",0,IFERROR(ROWS(_xlfn.UNIQUE(_xlfn._xlws.FILTER(Tabla3[PEDIDO],(Tabla3[STATUS]="COTIZANDO")*(Tabla3[NUM ECONOMICO]=B18)*(Tabla3[TEMA]<>"SERVICIO DE FILTROS")))),0))} -> 0 | F18: =IF(B18="",0,COUNTIFS(Tabla3[STATUS],"COTIZANDO",Tabla3[NUM ECONOMICO],B18,Tabla3[TEMA],"<>SERVICIO DE FILTROS")) -> 0 | G18: =IF(B18="",0,SUMIFS(Tabla3[COSTO TOTAL SIN IVA PESOS EN MATCO],Tabla3[STATUS],"COTIZANDO",Tabla3[NUM ECONOMICO],B18,Tabla3[TEMA],"<>SERVICIO DE FILTROS")) -> 0 | H18: =IF(B18="",0,SUMIFS(Tabla3[COSTO TOTAL DOLARES EN HAWTHORNE],Tabla3[STATUS],"COTIZANDO",Tabla3[NUM ECONOMICO],B18,Tabla3[TEMA],"<>SERVICIO DE FILTROS")) -> 0 | I18: =IF(B18="","",_xlfn.LET(_xlpm.totalUSD,SUMIFS(Tabla3[COSTO TOTAL DOLARES EN HAWTHORNE],Tabla3[STATUS],"COTIZANDO",Tabla3[NUM ECONOMICO],B18,Tabla3[TEMA],"<>SERVICIO DE FILTROS"),IF(OR(TC="",_xlpm.totalUSD=0),"—",_xlpm.totalUSD*TC))) -> — | J18: =IF(B18="",0,SUMIFS(Tabla3[COSTO TOTAL DOLARES CTP],Tabla3[STATUS],"COTIZANDO",Tabla3[NUM ECONOMICO],B18,Tabla3[TEMA],"<>SERVICIO DE FILTROS")) -> 0 | K18: =IF(B18="","",_xlfn.LET(_xlpm.totalUSD,SUMIFS(Tabla3[COSTO TOTAL DOLARES CTP],Tabla3[STATUS],"COTIZANDO",Tabla3[NUM ECONOMICO],B18,Tabla3[TEMA],"<>SERVICIO DE FILTROS"),IF(OR(TC="",_xlpm.totalUSD=0),"—",_xlpm.totalUSD*TC))) -> — | L18: {=IF(B18="",0,IFERROR(MAX(_xlfn._xlws.FILTER(Tabla3[DIAS DE ENTREGA TENTATIVO EN MATCO],(Tabla3[STATUS]="COTIZANDO")*(Tabla3[NUM ECONOMICO]=B18)*(Tabla3[TEMA]<>"SERVICIO DE FILTROS"))),0))} -> 0
B19: =MAQUINARIA!B420 -> CMX-01 | C19: =MAQUINARIA!H420 -> ACTIVA | D19: =IFERROR(TRIM(MAQUINARIA!C420&" "&MAQUINARIA!E420),"—") -> PLANTA DE CONCRETO MOVIL | E19: {=IF(B19="",0,IFERROR(ROWS(_xlfn.UNIQUE(_xlfn._xlws.FILTER(Tabla3[PEDIDO],(Tabla3[STATUS]="COTIZANDO")*(Tabla3[NUM ECONOMICO]=B19)*(Tabla3[TEMA]<>"SERVICIO DE FILTROS")))),0))} -> 0 | F19: =IF(B19="",0,COUNTIFS(Tabla3[STATUS],"COTIZANDO",Tabla3[NUM ECONOMICO],B19,Tabla3[TEMA],"<>SERVICIO DE FILTROS")) -> 0 | G19: =IF(B19="",0,SUMIFS(Tabla3[COSTO TOTAL SIN IVA PESOS EN MATCO],Tabla3[STATUS],"COTIZANDO",Tabla3[NUM ECONOMICO],B19,Tabla3[TEMA],"<>SERVICIO DE FILTROS")) -> 0 | H19: =IF(B19="",0,SUMIFS(Tabla3[COSTO TOTAL DOLARES EN HAWTHORNE],Tabla3[STATUS],"COTIZANDO",Tabla3[NUM ECONOMICO],B19,Tabla3[TEMA],"<>SERVICIO DE FILTROS")) -> 0 | I19: =IF(B19="","",_xlfn.LET(_xlpm.totalUSD,SUMIFS(Tabla3[COSTO TOTAL DOLARES EN HAWTHORNE],Tabla3[STATUS],"COTIZANDO",Tabla3[NUM ECONOMICO],B19,Tabla3[TEMA],"<>SERVICIO DE FILTROS"),IF(OR(TC="",_xlpm.totalUSD=0),"—",_xlpm.totalUSD*TC))) -> — | J19: =IF(B19="",0,SUMIFS(Tabla3[COSTO TOTAL DOLARES CTP],Tabla3[STATUS],"COTIZANDO",Tabla3[NUM ECONOMICO],B19,Tabla3[TEMA],"<>SERVICIO DE FILTROS")) -> 0 | K19: =IF(B19="","",_xlfn.LET(_xlpm.totalUSD,SUMIFS(Tabla3[COSTO TOTAL DOLARES CTP],Tabla3[STATUS],"COTIZANDO",Tabla3[NUM ECONOMICO],B19,Tabla3[TEMA],"<>SERVICIO DE FILTROS"),IF(OR(TC="",_xlpm.totalUSD=0),"—",_xlpm.totalUSD*TC))) -> — | L19: {=IF(B19="",0,IFERROR(MAX(_xlfn._xlws.FILTER(Tabla3[DIAS DE ENTREGA TENTATIVO EN MATCO],(Tabla3[STATUS]="COTIZANDO")*(Tabla3[NUM ECONOMICO]=B19)*(Tabla3[TEMA]<>"SERVICIO DE FILTROS"))),0))} -> 0
B20: =MAQUINARIA!B422 -> CRC-03 | C20: =MAQUINARIA!H422 -> ACTIVA | D20: =IFERROR(TRIM(MAQUINARIA!C422&" "&MAQUINARIA!E422),"—") -> CAMION REVOLVEDOR 7 MTS | E20: {=IF(B20="",0,IFERROR(ROWS(_xlfn.UNIQUE(_xlfn._xlws.FILTER(Tabla3[PEDIDO],(Tabla3[STATUS]="COTIZANDO")*(Tabla3[NUM ECONOMICO]=B20)*(Tabla3[TEMA]<>"SERVICIO DE FILTROS")))),0))} -> 0 | F20: =IF(B20="",0,COUNTIFS(Tabla3[STATUS],"COTIZANDO",Tabla3[NUM ECONOMICO],B20,Tabla3[TEMA],"<>SERVICIO DE FILTROS")) -> 0 | G20: =IF(B20="",0,SUMIFS(Tabla3[COSTO TOTAL SIN IVA PESOS EN MATCO],Tabla3[STATUS],"COTIZANDO",Tabla3[NUM ECONOMICO],B20,Tabla3[TEMA],"<>SERVICIO DE FILTROS")) -> 0 | H20: =IF(B20="",0,SUMIFS(Tabla3[COSTO TOTAL DOLARES EN HAWTHORNE],Tabla3[STATUS],"COTIZANDO",Tabla3[NUM ECONOMICO],B20,Tabla3[TEMA],"<>SERVICIO DE FILTROS")) -> 0 | I20: =IF(B20="","",_xlfn.LET(_xlpm.totalUSD,SUMIFS(Tabla3[COSTO TOTAL DOLARES EN HAWTHORNE],Tabla3[STATUS],"COTIZANDO",Tabla3[NUM ECONOMICO],B20,Tabla3[TEMA],"<>SERVICIO DE FILTROS"),IF(OR(TC="",_xlpm.totalUSD=0),"—",_xlpm.totalUSD*TC))) -> — | J20: =IF(B20="",0,SUMIFS(Tabla3[COSTO TOTAL DOLARES CTP],Tabla3[STATUS],"COTIZANDO",Tabla3[NUM ECONOMICO],B20,Tabla3[TEMA],"<>SERVICIO DE FILTROS")) -> 0 | K20: =IF(B20="","",_xlfn.LET(_xlpm.totalUSD,SUMIFS(Tabla3[COSTO TOTAL DOLARES CTP],Tabla3[STATUS],"COTIZANDO",Tabla3[NUM ECONOMICO],B20,Tabla3[TEMA],"<>SERVICIO DE FILTROS"),IF(OR(TC="",_xlpm.totalUSD=0),"—",_xlpm.totalUSD*TC))) -> — | L20: {=IF(B20="",0,IFERROR(MAX(_xlfn._xlws.FILTER(Tabla3[DIAS DE ENTREGA TENTATIVO EN MATCO],(Tabla3[STATUS]="COTIZANDO")*(Tabla3[NUM ECONOMICO]=B20)*(Tabla3[TEMA]<>"SERVICIO DE FILTROS"))),0))} -> 0
B21: =MAQUINARIA!B423 -> CRC-04 | C21: =MAQUINARIA!H423 -> INACTIVA | D21: =IFERROR(TRIM(MAQUINARIA!C423&" "&MAQUINARIA!E423),"—") -> CAMION REVOLVEDOR 7 MTS | E21: {=IF(B21="",0,IFERROR(ROWS(_xlfn.UNIQUE(_xlfn._xlws.FILTER(Tabla3[PEDIDO],(Tabla3[STATUS]="COTIZANDO")*(Tabla3[NUM ECONOMICO]=B21)*(Tabla3[TEMA]<>"SERVICIO DE FILTROS")))),0))} -> 0 | F21: =IF(B21="",0,COUNTIFS(Tabla3[STATUS],"COTIZANDO",Tabla3[NUM ECONOMICO],B21,Tabla3[TEMA],"<>SERVICIO DE FILTROS")) -> 0 | G21: =IF(B21="",0,SUMIFS(Tabla3[COSTO TOTAL SIN IVA PESOS EN MATCO],Tabla3[STATUS],"COTIZANDO",Tabla3[NUM ECONOMICO],B21,Tabla3[TEMA],"<>SERVICIO DE FILTROS")) -> 0 | H21: =IF(B21="",0,SUMIFS(Tabla3[COSTO TOTAL DOLARES EN HAWTHORNE],Tabla3[STATUS],"COTIZANDO",Tabla3[NUM ECONOMICO],B21,Tabla3[TEMA],"<>SERVICIO DE FILTROS")) -> 0 | I21: =IF(B21="","",_xlfn.LET(_xlpm.totalUSD,SUMIFS(Tabla3[COSTO TOTAL DOLARES EN HAWTHORNE],Tabla3[STATUS],"COTIZANDO",Tabla3[NUM ECONOMICO],B21,Tabla3[TEMA],"<>SERVICIO DE FILTROS"),IF(OR(TC="",_xlpm.totalUSD=0),"—",_xlpm.totalUSD*TC))) -> — | J21: =IF(B21="",0,SUMIFS(Tabla3[COSTO TOTAL DOLARES CTP],Tabla3[STATUS],"COTIZANDO",Tabla3[NUM ECONOMICO],B21,Tabla3[TEMA],"<>SERVICIO DE FILTROS")) -> 0 | K21: =IF(B21="","",_xlfn.LET(_xlpm.totalUSD,SUMIFS(Tabla3[COSTO TOTAL DOLARES CTP],Tabla3[STATUS],"COTIZANDO",Tabla3[NUM ECONOMICO],B21,Tabla3[TEMA],"<>SERVICIO DE FILTROS"),IF(OR(TC="",_xlpm.totalUSD=0),"—",_xlpm.totalUSD*TC))) -> — | L21: {=IF(B21="",0,IFERROR(MAX(_xlfn._xlws.FILTER(Tabla3[DIAS DE ENTREGA TENTATIVO EN MATCO],(Tabla3[STATUS]="COTIZANDO")*(Tabla3[NUM ECONOMICO]=B21)*(Tabla3[TEMA]<>"SERVICIO DE FILTROS"))),0))} -> 0
B22: =MAQUINARIA!B424 -> CRC-05 | C22: =MAQUINARIA!H424 -> ACTIVA | D22: =IFERROR(TRIM(MAQUINARIA!C424&" "&MAQUINARIA!E424),"—") -> CAMION REVOLVEDOR 7 MTS | E22: {=IF(B22="",0,IFERROR(ROWS(_xlfn.UNIQUE(_xlfn._xlws.FILTER(Tabla3[PEDIDO],(Tabla3[STATUS]="COTIZANDO")*(Tabla3[NUM ECONOMICO]=B22)*(Tabla3[TEMA]<>"SERVICIO DE FILTROS")))),0))} -> 0 | F22: =IF(B22="",0,COUNTIFS(Tabla3[STATUS],"COTIZANDO",Tabla3[NUM ECONOMICO],B22,Tabla3[TEMA],"<>SERVICIO DE FILTROS")) -> 0 | G22: =IF(B22="",0,SUMIFS(Tabla3[COSTO TOTAL SIN IVA PESOS EN MATCO],Tabla3[STATUS],"COTIZANDO",Tabla3[NUM ECONOMICO],B22,Tabla3[TEMA],"<>SERVICIO DE FILTROS")) -> 0 | H22: =IF(B22="",0,SUMIFS(Tabla3[COSTO TOTAL DOLARES EN HAWTHORNE],Tabla3[STATUS],"COTIZANDO",Tabla3[NUM ECONOMICO],B22,Tabla3[TEMA],"<>SERVICIO DE FILTROS")) -> 0 | I22: =IF(B22="","",_xlfn.LET(_xlpm.totalUSD,SUMIFS(Tabla3[COSTO TOTAL DOLARES EN HAWTHORNE],Tabla3[STATUS],"COTIZANDO",Tabla3[NUM ECONOMICO],B22,Tabla3[TEMA],"<>SERVICIO DE FILTROS"),IF(OR(TC="",_xlpm.totalUSD=0),"—",_xlpm.totalUSD*TC))) -> — | J22: =IF(B22="",0,SUMIFS(Tabla3[COSTO TOTAL DOLARES CTP],Tabla3[STATUS],"COTIZANDO",Tabla3[NUM ECONOMICO],B22,Tabla3[TEMA],"<>SERVICIO DE FILTROS")) -> 0 | K22: =IF(B22="","",_xlfn.LET(_xlpm.totalUSD,SUMIFS(Tabla3[COSTO TOTAL DOLARES CTP],Tabla3[STATUS],"COTIZANDO",Tabla3[NUM ECONOMICO],B22,Tabla3[TEMA],"<>SERVICIO DE FILTROS"),IF(OR(TC="",_xlpm.totalUSD=0),"—",_xlpm.totalUSD*TC))) -> — | L22: {=IF(B22="",0,IFERROR(MAX(_xlfn._xlws.FILTER(Tabla3[DIAS DE ENTREGA TENTATIVO EN MATCO],(Tabla3[STATUS]="COTIZANDO")*(Tabla3[NUM ECONOMICO]=B22)*(Tabla3[TEMA]<>"SERVICIO DE FILTROS"))),0))} -> 0
B23: =MAQUINARIA!B361 -> CV-01 | C23: =MAQUINARIA!H361 -> ACTIVA | D23: =IFERROR(TRIM(MAQUINARIA!C361&" "&MAQUINARIA!E361),"—") -> CAMION VOLTEO 7 M3 | E23: {=IF(B23="",0,IFERROR(ROWS(_xlfn.UNIQUE(_xlfn._xlws.FILTER(Tabla3[PEDIDO],(Tabla3[STATUS]="COTIZANDO")*(Tabla3[NUM ECONOMICO]=B23)*(Tabla3[TEMA]<>"SERVICIO DE FILTROS")))),0))} -> 0 | F23: =IF(B23="",0,COUNTIFS(Tabla3[STATUS],"COTIZANDO",Tabla3[NUM ECONOMICO],B23,Tabla3[TEMA],"<>SERVICIO DE FILTROS")) -> 0 | G23: =IF(B23="",0,SUMIFS(Tabla3[COSTO TOTAL SIN IVA PESOS EN MATCO],Tabla3[STATUS],"COTIZANDO",Tabla3[NUM ECONOMICO],B23,Tabla3[TEMA],"<>SERVICIO DE FILTROS")) -> 0 | H23: =IF(B23="",0,SUMIFS(Tabla3[COSTO TOTAL DOLARES EN HAWTHORNE],Tabla3[STATUS],"COTIZANDO",Tabla3[NUM ECONOMICO],B23,Tabla3[TEMA],"<>SERVICIO DE FILTROS")) -> 0 | I23: =IF(B23="","",_xlfn.LET(_xlpm.totalUSD,SUMIFS(Tabla3[COSTO TOTAL DOLARES EN HAWTHORNE],Tabla3[STATUS],"COTIZANDO",Tabla3[NUM ECONOMICO],B23,Tabla3[TEMA],"<>SERVICIO DE FILTROS"),IF(OR(TC="",_xlpm.totalUSD=0),"—",_xlpm.totalUSD*TC))) -> — | J23: =IF(B23="",0,SUMIFS(Tabla3[COSTO TOTAL DOLARES CTP],Tabla3[STATUS],"COTIZANDO",Tabla3[NUM ECONOMICO],B23,Tabla3[TEMA],"<>SERVICIO DE FILTROS")) -> 0 | K23: =IF(B23="","",_xlfn.LET(_xlpm.totalUSD,SUMIFS(Tabla3[COSTO TOTAL DOLARES CTP],Tabla3[STATUS],"COTIZANDO",Tabla3[NUM ECONOMICO],B23,Tabla3[TEMA],"<>SERVICIO DE FILTROS"),IF(OR(TC="",_xlpm.totalUSD=0),"—",_xlpm.totalUSD*TC))) -> — | L23: {=IF(B23="",0,IFERROR(MAX(_xlfn._xlws.FILTER(Tabla3[DIAS DE ENTREGA TENTATIVO EN MATCO],(Tabla3[STATUS]="COTIZANDO")*(Tabla3[NUM ECONOMICO]=B23)*(Tabla3[TEMA]<>"SERVICIO DE FILTROS"))),0))} -> 0
B24: =MAQUINARIA!B366 -> CV-02 | C24: =MAQUINARIA!H366 -> ACTIVA | D24: =IFERROR(TRIM(MAQUINARIA!C366&" "&MAQUINARIA!E366),"—") -> CAMION VOLTEO 11 M3 | E24: {=IF(B24="",0,IFERROR(ROWS(_xlfn.UNIQUE(_xlfn._xlws.FILTER(Tabla3[PEDIDO],(Tabla3[STATUS]="COTIZANDO")*(Tabla3[NUM ECONOMICO]=B24)*(Tabla3[TEMA]<>"SERVICIO DE FILTROS")))),0))} -> 0 | F24: =IF(B24="",0,COUNTIFS(Tabla3[STATUS],"COTIZANDO",Tabla3[NUM ECONOMICO],B24,Tabla3[TEMA],"<>SERVICIO DE FILTROS")) -> 0 | G24: =IF(B24="",0,SUMIFS(Tabla3[COSTO TOTAL SIN IVA PESOS EN MATCO],Tabla3[STATUS],"COTIZANDO",Tabla3[NUM ECONOMICO],B24,Tabla3[TEMA],"<>SERVICIO DE FILTROS")) -> 0 | H24: =IF(B24="",0,SUMIFS(Tabla3[COSTO TOTAL DOLARES EN HAWTHORNE],Tabla3[STATUS],"COTIZANDO",Tabla3[NUM ECONOMICO],B24,Tabla3[TEMA],"<>SERVICIO DE FILTROS")) -> 0 | I24: =IF(B24="","",_xlfn.LET(_xlpm.totalUSD,SUMIFS(Tabla3[COSTO TOTAL DOLARES EN HAWTHORNE],Tabla3[STATUS],"COTIZANDO",Tabla3[NUM ECONOMICO],B24,Tabla3[TEMA],"<>SERVICIO DE FILTROS"),IF(OR(TC="",_xlpm.totalUSD=0),"—",_xlpm.totalUSD*TC))) -> — | J24: =IF(B24="",0,SUMIFS(Tabla3[COSTO TOTAL DOLARES CTP],Tabla3[STATUS],"COTIZANDO",Tabla3[NUM ECONOMICO],B24,Tabla3[TEMA],"<>SERVICIO DE FILTROS")) -> 0 | K24: =IF(B24="","",_xlfn.LET(_xlpm.totalUSD,SUMIFS(Tabla3[COSTO TOTAL DOLARES CTP],Tabla3[STATUS],"COTIZANDO",Tabla3[NUM ECONOMICO],B24,Tabla3[TEMA],"<>SERVICIO DE FILTROS"),IF(OR(TC="",_xlpm.totalUSD=0),"—",_xlpm.totalUSD*TC))) -> — | L24: {=IF(B24="",0,IFERROR(MAX(_xlfn._xlws.FILTER(Tabla3[DIAS DE ENTREGA TENTATIVO EN MATCO],(Tabla3[STATUS]="COTIZANDO")*(Tabla3[NUM ECONOMICO]=B24)*(Tabla3[TEMA]<>"SERVICIO DE FILTROS"))),0))} -> 0
B25: =MAQUINARIA!B372 -> CV-03 | C25: =MAQUINARIA!H372 -> ACTIVA | D25: =IFERROR(TRIM(MAQUINARIA!C372&" "&MAQUINARIA!E372),"—") -> CAMION VOLTEO 9 M3 | E25: {=IF(B25="",0,IFERROR(ROWS(_xlfn.UNIQUE(_xlfn._xlws.FILTER(Tabla3[PEDIDO],(Tabla3[STATUS]="COTIZANDO")*(Tabla3[NUM ECONOMICO]=B25)*(Tabla3[TEMA]<>"SERVICIO DE FILTROS")))),0))} -> 0 | F25: =IF(B25="",0,COUNTIFS(Tabla3[STATUS],"COTIZANDO",Tabla3[NUM ECONOMICO],B25,Tabla3[TEMA],"<>SERVICIO DE FILTROS")) -> 0 | G25: =IF(B25="",0,SUMIFS(Tabla3[COSTO TOTAL SIN IVA PESOS EN MATCO],Tabla3[STATUS],"COTIZANDO",Tabla3[NUM ECONOMICO],B25,Tabla3[TEMA],"<>SERVICIO DE FILTROS")) -> 0 | H25: =IF(B25="",0,SUMIFS(Tabla3[COSTO TOTAL DOLARES EN HAWTHORNE],Tabla3[STATUS],"COTIZANDO",Tabla3[NUM ECONOMICO],B25,Tabla3[TEMA],"<>SERVICIO DE FILTROS")) -> 0 | I25: =IF(B25="","",_xlfn.LET(_xlpm.totalUSD,SUMIFS(Tabla3[COSTO TOTAL DOLARES EN HAWTHORNE],Tabla3[STATUS],"COTIZANDO",Tabla3[NUM ECONOMICO],B25,Tabla3[TEMA],"<>SERVICIO DE FILTROS"),IF(OR(TC="",_xlpm.totalUSD=0),"—",_xlpm.totalUSD*TC))) -> — | J25: =IF(B25="",0,SUMIFS(Tabla3[COSTO TOTAL DOLARES CTP],Tabla3[STATUS],"COTIZANDO",Tabla3[NUM ECONOMICO],B25,Tabla3[TEMA],"<>SERVICIO DE FILTROS")) -> 0 | K25: =IF(B25="","",_xlfn.LET(_xlpm.totalUSD,SUMIFS(Tabla3[COSTO TOTAL DOLARES CTP],Tabla3[STATUS],"COTIZANDO",Tabla3[NUM ECONOMICO],B25,Tabla3[TEMA],"<>SERVICIO DE FILTROS"),IF(OR(TC="",_xlpm.totalUSD=0),"—",_xlpm.totalUSD*TC))) -> — | L25: {=IF(B25="",0,IFERROR(MAX(_xlfn._xlws.FILTER(Tabla3[DIAS DE ENTREGA TENTATIVO EN MATCO],(Tabla3[STATUS]="COTIZANDO")*(Tabla3[NUM ECONOMICO]=B25)*(Tabla3[TEMA]<>"SERVICIO DE FILTROS"))),0))} -> 0
